Workbook

Sheet 摘要
A1: TON 滚仓收益与强平风险摘要
A2: 默认案例：1.5 -> 40，滚仓 12 段，目标杠杆 2.5x。请先在“参数”页替换为真实交易所参数。
A4: 核心结果 | F4: 风险解释
A5: 现货最终倍数 | B5: =参数!B23 -> 26.666667 | C5: x | D5: 不加杠杆，仅价格上涨 | F5: 1
A6: U本位最终权益 | B6: =LOOKUP(2,1/(U本位滚仓!A5:A28<>""),U本位滚仓!M5:M28) -> 9846972.9 | C6: USDT | D6: 来自 U本位滚仓最后一段
A7: U本位最终倍数 | B7: =B6/参数!B5 -> 984.69729 | C7: x | D7: 最终权益 / 初始本金
A8: U本位估算强平次数 | B8: =COUNTIF(U本位滚仓!R5:R28,"*强平*") -> 0 | C8: 次 | D8: 段内插针低点低于估算强平价
A9: U本位最大安全杠杆 | B9: =参数!B21 -> 2.8153153 | C9: x | D9: 可承受参数页最大回撤的理论上限
A10: 币本位最终权益 | B10: =LOOKUP(2,1/(币本位滚仓!A5:A28<>""),币本位滚仓!O5:O28) -> 70017053 | C10: USDT | D10: 来自币本位滚仓最后一段
A11: 币本位最终倍数 | B11: =B10/参数!B5 -> 7001.7053 | C11: x | D11: 最终权益 / 初始本金
A12: 币本位估算强平次数 | B12: =COUNTIF(币本位滚仓!T5:T28,"*强平*") -> 0 | C12: 次 | D12: 段内插针低点低于估算强平价
A13: 币本位最大安全杠杆 | B13: =参数!B22 -> 1.8156425 | C13: x | D13: 币本位逆向合约的理论上限
A14: 风险预算滚仓目标权益 | B14: =INDEX(风险预算滚仓!R5:R16,MIN(参数!$B$29,ROWS(风险预算滚仓!R5:R16))) -> 3390808.3 | C14: USDT | D14: 来自风险预算滚仓最后一笔加仓后的目标价权益
A15: 风险预算滚仓最终倍数 | B15: =B14/参数!$B$5 -> 339.08083 | C15: x | D15: 目标价权益 / 初始本金
A16: 目标币仓降杠杆最终资产 | B16: =目标币仓降杠杆!J16 -> 42231958 | C16: USDT | D16: 对应新增模式最后一行资产总额
A17: 目标币仓降杠杆最终倍数 | B17: =B16/参数!$B$5 -> 4223.1958 | C17: x | D17: 最终资产 / 初始本金
A18: 图表数据 | B18: 现货 | C18: U本位 | D18: 币本位 | E18: 风险预算
A19: 最终倍数 | B19: =B5 -> 26.666667 | C19: =B7 -> 984.69729 | D19: =B11 -> 7001.7053 | E19: =B15 -> 339.08083
A20: 图表数据 | B20: 最终倍数 | C20: 强平/风险次数 | D20: 说明
A21: 现货 | B21: =B5 -> 26.666667 | C21: 0 | D21: 不使用杠杆
A22: U本位 | B22: =B7 -> 984.69729 | C22: =B8 -> 0 | D22: 固定目标杠杆复投
A23: 币本位 | B23: =B11 -> 7001.7053 | C23: =B12 -> 0 | D23: 币本位固定目标杠杆
A24: 风险预算 | B24: =B15 -> 339.08083 | C24: 0 | D24: 分笔加仓，控制单笔风险
A25: 目标币仓降杠杆 | B25: =B17 -> 4223.1958 | C25: 0 | D25: 盈利后降杠杆，维持目标币仓

Sheet 图表
A1: 滚仓模式图表
A2: 图表引用摘要页和各模式页公式。修改参数后，Excel 打开并重算即可更新。
A4: 模式 | B4: 最终倍数 | C4: 风险次数
A5: 现货 | B5: =摘要!B5 -> 26.666667 | C5: 0
A6: U本位 | B6: =摘要!B7 -> 984.69729 | C6: =摘要!B8 -> 0
A7: 币本位 | B7: =摘要!B11 -> 7001.7053 | C7: =摘要!B12 -> 0
A8: 风险预算 | B8: =摘要!B15 -> 339.08083 | C8: 0
A9: 目标币仓降杠杆 | B9: =摘要!B17 -> 4223.1958 | C9: 0
A15: Step | B15: TON单价 | C15: 使用杠杆 | D15: 资产总额U
A16: =目标币仓降杠杆!A5 -> 0 | B16: =目标币仓降杠杆!C5 -> 1.5 | C16: =目标币仓降杠杆!G5 -> 10 | D16: =目标币仓降杠杆!J5 -> 10000
A17: =目标币仓降杠杆!A6 -> 1 | B17: =目标币仓降杠杆!C6 -> 1.56 | C17: =目标币仓降杠杆!G6 -> 8 | D17: =目标币仓降杠杆!J6 -> 14307
A18: =目标币仓降杠杆!A7 -> 2 | B18: =目标币仓降杠杆!C7 -> 1.638 | C18: =目标币仓降杠杆!G7 -> 6 | D18: =目标币仓降杠杆!J7 -> 20637.848
A19: =目标币仓降杠杆!A8 -> 3 | B19: =目标币仓降杠杆!C8 -> 1.7199 | C19: =目标币仓降杠杆!G8 -> 5 | D19: =目标币仓降杠杆!J8 -> 27745.006
A20: =目标币仓降杠杆!A9 -> 4 | B20: =目标币仓降杠杆!C9 -> 1.840293 | C20: =目标币仓降杠杆!G9 -> 4 | D20: =目标币仓降杠杆!J9 -> 39265.773
A21: =目标币仓降杠杆!A10 -> 5 | B21: =目标币仓降杠杆!C10 -> 2.0243223 | C21: =目标币仓降杠杆!G10 -> 3 | D21: =目标币仓降杠杆!J10 -> 58745.523
A22: =目标币仓降杠杆!A11 -> 6 | B22: =目标币仓降杠杆!C11 -> 2.4291868 | C22: =目标币仓降杠杆!G11 -> 2 | D22: =目标币仓降杠杆!J11 -> 105556.89
A23: =目标币仓降杠杆!A12 -> 7 | B23: =目标币仓降杠杆!C12 -> 3.2794021 | C23: =目标币仓降杠杆!G12 -> 1.5 | D23: =目标币仓降杠杆!J12 -> 216146.21
A24: =目标币仓降杠杆!A13 -> 8 | B24: =目标币仓降杠杆!C13 -> 4.9191032 | C24: =目标币仓降杠杆!G13 -> 1 | D24: =目标币仓降杠杆!J13 -> 485915.6
A25: =目标币仓降杠杆!A14 -> 9 | B25: =目标币仓降杠杆!C14 -> 9.8382064 | C25: =目标币仓降杠杆!G14 -> 0.5 | D25: =目标币仓降杠杆!J14 -> 1456945
A26: =目标币仓降杠杆!A15 -> 10 | B26: =目标币仓降杠杆!C15 -> 29.514619 | C26: =目标币仓降杠杆!G15 -> 0.25 | D26: =目标币仓降杠杆!J15 -> 5826031.8
A27: =目标币仓降杠杆!A16 -> 11 | B27: =目标币仓降杠杆!C16 -> 177.08771 | C27: =目标币仓降杠杆!G16 -> 0.1 | D27: =目标币仓降杠杆!J16 -> 42231958

Sheet 参数
A1: TON / TONX 滚仓试算参数
A2: 黄色单元格为可改输入。模型用于杠杆滚仓的路径和风险试算，不构成投资建议。
A4: 核心价格与仓位参数
A5: 初始本金 | B5: 10000 | C5: USDT | D5: 用于两套模型的起始权益
A6: 初始币价 | B6: 1.5 | C6: USDT/TON | D6: 第一段滚仓的起点价格
A7: 目标币价 | B7: 40 | C7: USDT/TON | D7: 模型终点价格
A8: 滚仓段数 | B8: 12 | C8: 段 | D8: 价格路径按几何等比切分
A9: 目标杠杆 | B9: 2.5 | C9: x | D9: 每段开仓后把权益重新调到该杠杆
A10: 最大容忍回撤 | B10: 0.35 | C10: % | D10: 希望从开仓价向下最多承受的回撤
A11: 维持保证金率 | B11: 0.005 | C11: % | D11: 交易所档位参数，需按实际合约替换
A12: 强平/保险缓冲 | B12: 0.003 | C12: % | D12: 用于模拟强平费、保险基金和规则差异
A13: 单边交易费率 | B13: 0.0006 | C13: % | D13: 每次开仓和每次平仓各收一次
A14: 单边滑点 | B14: 0.001 | C14: % | D14: 开多买贵、平多卖便宜的执行价折损
A15: 每期资金费率 | B15: 0.0001 | C15: % | D15: 正数代表多头支付，负数代表多头收取
A16: 每段资金费次数 | B16: 3 | C16: 次 | D16: 例如每 8 小时一次，持仓 24 小时为 3 次
... A19: 默认滚仓最大行数 | B19: 24 | C19: 段 | D19: 表格预留段数
A20: 当前价格路径 | B20: 几何等比 | D20: EndPrice = 初始价 * (目标价/初始价)^(Step/滚仓段数)
A21: U本位最大安全杠杆 | B21: =1/(1-(1-B10)*(1-B11-B12)) -> 2.8153153 | C21: x | D21: 由最大回撤、维持保证金和强平缓冲反推
A22: 币本位最大安全杠杆 | B22: =(1-B10)/(B10+B11+B12) -> 1.8156425 | C22: x | D22: 币本位逆向合约因保证金币价同步下跌，安全杠杆更低
A23: 现货最终倍数 | B23: =B7/B6 -> 26.666667 | C23: x | D23: 目标币价 / 初始币价
A24: 目标杠杆是否超限 | B24: =IF(OR(B9>B21,B9>B22),"检查杠杆","OK") -> 检查杠杆 | D24: 会同时检查 U 本位和币本位
A25: 风险预算-单次保证金比例 | B25: 0.1 | C25: % | D25: 图中示例类似：总资金只拿 10% 做单次保证金
A26: 风险预算-单笔合约杠杆 | B26: 10 | C26: x | D26: 图中示例类似：单笔使用 10 倍杠杆
A27: 风险预算-单笔止损幅度 | B27: 0.02 | C27: % | D27: 图中示例类似：2% 止损
A28: 风险预算-加仓触发涨幅 | B28: 0.1 | C28: % | D28: 价格每上涨该幅度，模型新增一笔趋势仓
A29: 风险预算-最大加仓次数 | B29: 8 | C29: 次 | D29: 风险预算滚仓页预留 12 次，默认只启用前 8 次
A31: 颜色约定
A32: 蓝色字体 + 黄色底 | B32: 用户输入 | D32: 可按交易所实际费率、维持保证金、资金费率修改
A33: 黑色字体 | B33: 公式 | D33: 模型计算项
A34: 绿色状态 | B34: OK | D34: 没有触发对应检查
A35: 红色/黄色状态 | B35: 风险提示 | D35: 杠杆、插针或强平缓冲需要复核

Sheet U本位滚仓
A1: U本位滚仓明细
A2: 线性 USDT 保证金模型：盈亏以 USDT 结算。强平价使用简化公式，实际以交易所标记价格和档位为准。
A4: Step | B4: 起始价 | C4: 目标/结束价 | D4: 开仓执行价 | E4: 平仓执行价 | F4: 期初权益 | G4: 名义仓位 | H4: 持币数量 | I4: 开仓费 | J4: 资金费 | K4: 毛盈亏 | L4: 平仓费 | M4: 期末权益 | N4: 滚仓倍数 | O4: 估算强平价 | P4: 段内插针低点 | Q4: 强平缓冲 | R4: 状态
A5: =IF(ROW()-4<=参数!$B$8,ROW()-4,"") -> 1 | B5: =IF($A5="","",IF($A5=1,参数!$B$6,C4)) -> 1.5 | C5: =IF($A5="","",参数!$B$6*(参数!$B$7/参数!$B$6)^($A5/参数!$B$8)) -> 1.9720685 | D5: =IF($A5="","",B5*(1+参数!$B$14)) -> 1.5015 | E5: =IF($A5="","",C5*(1-参数!$B$14)) -> 1.9700964 | F5: =IF($A5="","",IF($A5=1,参数!$B$5,M4)) -> 10000 | G5: =IF($A5="","",F5*参数!$B$9) -> 25000 | H5: =IF($A5="","",G5/D5) -> 16650.017 | I5: =IF($A5="","",G5*参数!$B$13) -> 15 | J5: =IF($A5="","",G5*参数!$B$15*参数!$B$16) -> 7.5 | K5: =IF($A5="","",H5*(E5-D5)) -> 7802.1377 | L5: =IF($A5="","",H5*E5*参数!$B$13) -> 19.681283 | M5: =IF($A5="","",MAX(0,F5+K5-I5-J5-L5)) -> 17759.956 | N5: =IF($A5="","",M5/F5) -> 1.7759956 | O5: =IF($A5="","",D5*(1-1/参数!$B$9)/(1-参数!$B$11-参数!$B$12)) -> 0.90816532 | P5: =IF($A5="","",B5*(1-参数!$B$17)) -> 1.2 | Q5: =IF($A5="","",P5/O5-1) -> 0.32134532 | R5: =IF($A5="","",IF(P5<=O5,"插针触发强平","OK")) -> OK
A6: =IF(ROW()-4<=参数!$B$8,ROW()-4,"") -> 2 | B6: =IF($A6="","",IF($A6=1,参数!$B$6,C5)) -> 1.9720685 | C6: =IF($A6="","",参数!$B$6*(参数!$B$7/参数!$B$6)^($A6/参数!$B$8)) -> 2.5927027 | D6: =IF($A6="","",B6*(1+参数!$B$14)) -> 1.9740405 | E6: =IF($A6="","",C6*(1-参数!$B$14)) -> 2.59011 | F6: =IF($A6="","",IF($A6=1,参数!$B$5,M5)) -> 17759.956 | G6: =IF($A6="","",F6*参数!$B$9) -> 44399.891 | H6: =IF($A6="","",G6/D6) -> 22491.884 | I6: =IF($A6="","",G6*参数!$B$13) -> 26.639935 | J6: =IF($A6="","",G6*参数!$B$15*参数!$B$16) -> 13.319967 | K6: =IF($A6="","",H6*(E6-D6)) -> 13856.562 | L6: =IF($A6="","",H6*E6*参数!$B$13) -> 34.953872 | M6: =IF($A6="","",MAX(0,F6+K6-I6-J6-L6)) -> 31541.605 | N6: =IF($A6="","",M6/F6) -> 1.7759956 | O6: =IF($A6="","",D6*(1-1/参数!$B$9)/(1-参数!$B$11-参数!$B$12)) -> 1.1939761 | P6: =IF($A6="","",B6*(1-参数!$B$17)) -> 1.5776548 | Q6: =IF($A6="","",P6/O6-1) -> 0.32134532 | R6: =IF($A6="","",IF(P6<=O6,"插针触发强平","OK")) -> OK
A7: =IF(ROW()-4<=参数!$B$8,ROW()-4,"") -> 3 | B7: =IF($A7="","",IF($A7=1,参数!$B$6,C6)) -> 2.5927027 | C7: =IF($A7="","",参数!$B$6*(参数!$B$7/参数!$B$6)^($A7/参数!$B$8)) -> 3.4086581 | D7: =IF($A7="","",B7*(1+参数!$B$14)) -> 2.5952954 | E7: =IF($A7="","",C7*(1-参数!$B$14)) -> 3.4052494 | F7: =IF($A7="","",IF($A7=1,参数!$B$5,M6)) -> 31541.605 | G7: =IF($A7="","",F7*参数!$B$9) -> 78854.013 | H7: =IF($A7="","",G7/D7) -> 30383.444 | I7: =IF($A7="","",G7*参数!$B$13) -> 47.312408 | J7: =IF($A7="","",G7*参数!$B$15*参数!$B$16) -> 23.656204 | K7: =IF($A7="","",H7*(E7-D7)) -> 24609.195 | L7: =IF($A7="","",H7*E7*参数!$B$13) -> 62.077924 | M7: =IF($A7="","",MAX(0,F7+K7-I7-J7-L7)) -> 56017.753 | N7: =IF($A7="","",M7/F7) -> 1.7759956 | O7: =IF($A7="","",D7*(1-1/参数!$B$9)/(1-参数!$B$11-参数!$B$12)) -> 1.5697351 | P7: =IF($A7="","",B7*(1-参数!$B$17)) -> 2.0741621 | Q7: =IF($A7="","",P7/O7-1) -> 0.32134532 | R7: =IF($A7="","",IF(P7<=O7,"插针触发强平","OK")) -> OK
A8: =IF(ROW()-4<=参数!$B$8,ROW()-4,"") -> 4 | B8: =IF($A8="","",IF($A8=1,参数!$B$6,C7)) -> 3.4086581 | C8: =IF($A8="","",参数!$B$6*(参数!$B$7/参数!$B$6)^($A8/参数!$B$8)) -> 4.4814047 | D8: =IF($A8="","",B8*(1+参数!$B$14)) -> 3.4120668 | E8: =IF($A8="","",C8*(1-参数!$B$14)) -> 4.4769233 | F8: =IF($A8="","",IF($A8=1,参数!$B$5,M7)) -> 56017.753 | G8: =IF($A8="","",F8*参数!$B$9) -> 140044.38 | H8: =IF($A8="","",G8/D8) -> 41043.858 | I8: =IF($A8="","",G8*参数!$B$13) -> 84.02663 | J8: =IF($A8="","",G8*参数!$B$15*参数!$B$16) -> 42.013315 | K8: =IF($A8="","",H8*(E8-D8)) -> 43705.822 | L8: =IF($A8="","",H8*E8*参数!$B$13) -> 110.25012 | M8: =IF($A8="","",MAX(0,F8+K8-I8-J8-L8)) -> 99487.285 | N8: =IF($A8="","",M8/F8) -> 1.7759956 | O8: =IF($A8="","",D8*(1-1/参数!$B$9)/(1-参数!$B$11-参数!$B$12)) -> 2.0637501 | P8: =IF($A8="","",B8*(1-参数!$B$17)) -> 2.7269265 | Q8: =IF($A8="","",P8/O8-1) -> 0.32134532 | R8: =IF($A8="","",IF(P8<=O8,"插针触发强平","OK")) -> OK
A9: =IF(ROW()-4<=参数!$B$8,ROW()-4,"") -> 5 | B9: =IF($A9="","",IF($A9=1,参数!$B$6,C8)) -> 4.4814047 | C9: =IF($A9="","",参数!$B$6*(参数!$B$7/参数!$B$6)^($A9/参数!$B$8)) -> 5.891758 | D9: =IF($A9="","",B9*(1+参数!$B$14)) -> 4.4858862 | E9: =IF($A9="","",C9*(1-参数!$B$14)) -> 5.8858662 | F9: =IF($A9="","",IF($A9=1,参数!$B$5,M8)) -> 99487.285 | G9: =IF($A9="","",F9*参数!$B$9) -> 248718.21 | H9: =IF($A9="","",G9/D9) -> 55444.611 | I9: =IF($A9="","",G9*参数!$B$13) -> 149.23093 | J9: =IF($A9="","",G9*参数!$B$15*参数!$B$16) -> 74.615464 | K9: =IF($A9="","",H9*(E9-D9)) -> 77621.35 | L9: =IF($A9="","",H9*E9*参数!$B$13) -> 195.80374 | M9: =IF($A9="","",MAX(0,F9+K9-I9-J9-L9)) -> 176688.98 | N9: =IF($A9="","",M9/F9) -> 1.7759956 | O9: =IF($A9="","",D9*(1-1/参数!$B$9)/(1-参数!$B$11-参数!$B$12)) -> 2.7132376 | P9: =IF($A9="","",B9*(1-参数!$B$17)) -> 3.5851238 | Q9: =IF($A9="","",P9/O9-1) -> 0.32134532 | R9: =IF($A9="","",IF(P9<=O9,"插针触发强平","OK")) -> OK
A10: =IF(ROW()-4<=参数!$B$8,ROW()-4,"") -> 6 | B10: =IF($A10="","",IF($A10=1,参数!$B$6,C9)) -> 5.891758 | C10: =IF($A10="","",参数!$B$6*(参数!$B$7/参数!$B$6)^($A10/参数!$B$8)) -> 7.7459667 | D10: =IF($A10="","",B10*(1+参数!$B$14)) -> 5.8976497 | E10: =IF($A10="","",C10*(1-参数!$B$14)) -> 7.7382207 | F10: =IF($A10="","",IF($A10=1,参数!$B$5,M9)) -> 176688.98 | G10: =IF($A10="","",F10*参数!$B$9) -> 441722.46 | H10: =IF($A10="","",G10/D10) -> 74898.05 | I10: =IF($A10="","",G10*参数!$B$13) -> 265.03348 | J10: =IF($A10="","",G10*参数!$B$15*参数!$B$16) -> 132.51674 | K10: =IF($A10="","",H10*(E10-D10)) -> 137855.18 | L10: =IF($A10="","",H10*E10*参数!$B$13) -> 347.74658 | M10: =IF($A10="","",MAX(0,F10+K10-I10-J10-L10)) -> 313798.87 | N10: =IF($A10="","",M10/F10) -> 1.7759956 | O10: =IF($A10="","",D10*(1-1/参数!$B$9)/(1-参数!$B$11-参数!$B$12)) -> 3.5671268 | P10: =IF($A10="","",B10*(1-参数!$B$17)) -> 4.7134064 | Q10: =IF($A10="","",P10/O10-1) -> 0.32134532 | R10: =IF($A10="","",IF(P10<=O10,"插针触发强平","OK")) -> OK
A11: =IF(ROW()-4<=参数!$B$8,ROW()-4,"") -> 7 | B11: =IF($A11="","",IF($A11=1,参数!$B$6,C10)) -> 7.7459667 | C11: =IF($A11="","",参数!$B$6*(参数!$B$7/参数!$B$6)^($A11/参数!$B$8)) -> 10.183718 | D11: =IF($A11="","",B11*(1+参数!$B$14)) -> 7.7537127 | E11: =IF($A11="","",C11*(1-参数!$B$14)) -> 10.173534 | F11: =IF($A11="","",IF($A11=1,参数!$B$5,M10)) -> 313798.87 | G11: =IF($A11="","",F11*参数!$B$9) -> 784497.17 | H11: =IF($A11="","",G11/D11) -> 101176.97 | I11: =IF($A11="","",G11*参数!$B$13) -> 470.6983 | J11: =IF($A11="","",G11*参数!$B$15*参数!$B$16) -> 235.34915 | K11: =IF($A11="","",H11*(E11-D11)) -> 244830.2 | L11: =IF($A11="","",H11*E11*参数!$B$13) -> 617.59642 | M11: =IF($A11="","",MAX(0,F11+K11-I11-J11-L11)) -> 557305.42 | N11: =IF($A11="","",M11/F11) -> 1.7759956 | O11: =IF($A11="","",D11*(1-1/参数!$B$9)/(1-参数!$B$11-参数!$B$12)) -> 4.6897456 | P11: =IF($A11="","",B11*(1-参数!$B$17)) -> 6.1967734 | Q11: =IF($A11="","",P11/O11-1) -> 0.32134532 | R11: =IF($A11="","",IF(P11<=O11,"插针触发强平","OK")) -> OK
A12: =IF(ROW()-4<=参数!$B$8,ROW()-4,"") -> 8 | B12: =IF($A12="","",IF($A12=1,参数!$B$6,C11)) -> 10.183718 | C12: =IF($A12="","",参数!$B$6*(参数!$B$7/参数!$B$6)^($A12/参数!$B$8)) -> 13.388659 | D12: =IF($A12="","",B12*(1+参数!$B$14)) -> 10.193901 | E12: =IF($A12="","",C12*(1-参数!$B$14)) -> 13.37527 | F12: =IF($A12="","",IF($A12=1,参数!$B$5,M11)) -> 557305.42 | G12: =IF($A12="","",F12*参数!$B$9) -> 1393263.5 | H12: =IF($A12="","",G12/D12) -> 136676.18 | I12: =IF($A12="","",G12*参数!$B$13) -> 835.95813 | J12: =IF($A12="","",G12*参数!$B$15*参数!$B$16) -> 417.97906 | K12: =IF($A12="","",H12*(E12-D12)) -> 434817.36 | L12: =IF($A12="","",H12*E12*参数!$B$13) -> 1096.8485 | M12: =IF($A12="","",MAX(0,F12+K12-I12-J12-L12)) -> 989771.99 | N12: =IF($A12="","",M12/F12) -> 1.7759956 | O12: =IF($A12="","",D12*(1-1/参数!$B$9)/(1-参数!$B$11-参数!$B$12)) -> 6.1656662 | P12: =IF($A12="","",B12*(1-参数!$B$17)) -> 8.1469742 | Q12: =IF($A12="","",P12/O12-1) -> 0.32134532 | R12: =IF($A12="","",IF(P12<=O12,"插针触发强平","OK")) -> OK
A13: =IF(ROW()-4<=参数!$B$8,ROW()-4,"") -> 9 | B13: =IF($A13="","",IF($A13=1,参数!$B$6,C12)) -> 13.388659 | C13: =IF($A13="","",参数!$B$6*(参数!$B$7/参数!$B$6)^($A13/参数!$B$8)) -> 17.602235 | D13: =IF($A13="","",B13*(1+参数!$B$14)) -> 13.402048 | E13: =IF($A13="","",C13*(1-参数!$B$14)) -> 17.584633 | F13: =IF($A13="","",IF($A13=1,参数!$B$5,M12)) -> 989771.99 | G13: =IF($A13="","",F13*参数!$B$9) -> 2474430 | H13: =IF($A13="","",G13/D13) -> 184630.74 | I13: =IF($A13="","",G13*参数!$B$13) -> 1484.658 | J13: =IF($A13="","",G13*参数!$B$15*参数!$B$16) -> 742.329 | K13: =IF($A13="","",H13*(E13-D13)) -> 772233.74 | L13: =IF($A13="","",H13*E13*参数!$B$13) -> 1947.9982 | M13: =IF($A13="","",MAX(0,F13+K13-I13-J13-L13)) -> 1757830.7 | N13: =IF($A13="","",M13/F13) -> 1.7759956 | O13: =IF($A13="","",D13*(1-1/参数!$B$9)/(1-参数!$B$11-参数!$B$12)) -> 8.1060772 | P13: =IF($A13="","",B13*(1-参数!$B$17)) -> 10.710927 | Q13: =IF($A13="","",P13/O13-1) -> 0.32134532 | R13: =IF($A13="","",IF(P13<=O13,"插针触发强平","OK")) -> OK
A14: =IF(ROW()-4<=参数!$B$8,ROW()-4,"") -> 10 | B14: =IF($A14="","",IF($A14=1,参数!$B$6,C13)) -> 17.602235 | C14: =IF($A14="","",参数!$B$6*(参数!$B$7/参数!$B$6)^($A14/参数!$B$8)) -> 23.141875 | D14: =IF($A14="","",B14*(1+参数!$B$14)) -> 17.619837 | E14: =IF($A14="","",C14*(1-参数!$B$14)) -> 23.118733 | F14: =IF($A14="","",IF($A14=1,参数!$B$5,M13)) -> 1757830.7 | G14: =IF($A14="","",F14*参数!$B$9) -> 4394576.9 | H14: =IF($A14="","",G14/D14) -> 249410.76 | I14: =IF($A14="","",G14*参数!$B$13) -> 2636.7461 | J14: =IF($A14="","",G14*参数!$B$15*参数!$B$16) -> 1318.3731 | K14: =IF($A14="","",H14*(E14-D14)) -> 1371483.7 | L14: =IF($A14="","",H14*E14*参数!$B$13) -> 3459.6364 | M14: =IF($A14="","",MAX(0,F14+K14-I14-J14-L14)) -> 3121899.7 | N14: =IF($A14="","",M14/F14) -> 1.7759956 | O14: =IF($A14="","",D14*(1-1/参数!$B$9)/(1-参数!$B$11-参数!$B$12)) -> 10.657159 | P14: =IF($A14="","",B14*(1-参数!$B$17)) -> 14.081788 | Q14: =IF($A14="","",P14/O14-1) -> 0.32134532 | R14: =IF($A14="","",IF(P14<=O14,"插针触发强平","OK")) -> OK
A15: =IF(ROW()-4<=参数!$B$8,ROW()-4,"") -> 11 | B15: =IF($A15="","",IF($A15=1,参数!$B$6,C14)) -> 23.141875 | C15: =IF($A15="","",参数!$B$6*(参数!$B$7/参数!$B$6)^($A15/参数!$B$8)) -> 30.424907 | D15: =IF($A15="","",B15*(1+参数!$B$14)) -> 23.165016 | E15: =IF($A15="","",C15*(1-参数!$B$14)) -> 30.394482 | F15: =IF($A15="","",IF($A15=1,参数!$B$5,M14)) -> 3121899.7 | G15: =IF($A15="","",F15*参数!$B$9) -> 7804749.3 | H15: =IF($A15="","",G15/D15) -> 336919.65 | I15: =IF($A15="","",G15*参数!$B$13) -> 4682.8496 | J15: =IF($A15="","",G15*参数!$B$15*参数!$B$16) -> 2341.4248 | K15: =IF($A15="","",H15*(E15-D15)) -> 2435749.2 | L15: =IF($A15="","",H15*E15*参数!$B$13) -> 6144.2991 | M15: =IF($A15="","",MAX(0,F15+K15-I15-J15-L15)) -> 5544480.3 | N15: =IF($A15="","",M15/F15) -> 1.7759956 | O15: =IF($A15="","",D15*(1-1/参数!$B$9)/(1-参数!$B$11-参数!$B$12)) -> 14.011099 | P15: =IF($A15="","",B15*(1-参数!$B$17)) -> 18.5135 | Q15: =IF($A15="","",P15/O15-1) -> 0.32134532 | R15: =IF($A15="","",IF(P15<=O15,"插针触发强平","OK")) -> OK
A16: =IF(ROW()-4<=参数!$B$8,ROW()-4,"") -> 12 | B16: =IF($A16="","",IF($A16=1,参数!$B$6,C15)) -> 30.424907 | C16: =IF($A16="","",参数!$B$6*(参数!$B$7/参数!$B$6)^($A16/参数!$B$8)) -> 40 | D16: =IF($A16="","",B16*(1+参数!$B$14)) -> 30.455332 | E16: =IF($A16="","",C16*(1-参数!$B$14)) -> 39.96 | F16: =IF($A16="","",IF($A16=1,参数!$B$5,M15)) -> 5544480.3 | G16: =IF($A16="","",F16*参数!$B$9) -> 13861201 | H16: =IF($A16="","",G16/D16) -> 455132.15 | I16: =IF($A16="","",G16*参数!$B$13) -> 8316.7205 | J16: =IF($A16="","",G16*参数!$B$15*参数!$B$16) -> 4158.3602 | K16: =IF($A16="","",H16*(E16-D16)) -> 4325879.9 | L16: =IF($A16="","",H16*E16*参数!$B$13) -> 10912.248 | M16: =IF($A16="","",MAX(0,F16+K16-I16-J16-L16)) -> 9846972.9 | N16: =IF($A16="","",M16/F16) -> 1.7759956 | O16: =IF($A16="","",D16*(1-1/参数!$B$9)/(1-参数!$B$11-参数!$B$12)) -> 18.420564 | P16: =IF($A16="","",B16*(1-参数!$B$17)) -> 24.339926 | Q16: =IF($A16="","",P16/O16-1) -> 0.32134532 | R16: =IF($A16="","",IF(P16<=O16,"插针触发强平","OK")) -> OK
... A28: =IF(ROW()-4<=参数!$B$8,ROW()-4,"") | B28: =IF($A28="","",IF($A28=1,参数!$B$6,C27)) | C28: =IF($A28="","",参数!$B$6*(参数!$B$7/参数!$B$6)^($A28/参数!$B$8)) | D28: =IF($A28="","",B28*(1+参数!$B$14)) | E28: =IF($A28="","",C28*(1-参数!$B$14)) | F28: =IF($A28="","",IF($A28=1,参数!$B$5,M27)) | G28: =IF($A28="","",F28*参数!$B$9) | H28: =IF($A28="","",G28/D28) | I28: =IF($A28="","",G28*参数!$B$13) | J28: =IF($A28="","",G28*参数!$B$15*参数!$B$16) | K28: =IF($A28="","",H28*(E28-D28)) | L28: =IF($A28="","",H28*E28*参数!$B$13) | M28: =IF($A28="","",MAX(0,F28+K28-I28-J28-L28)) | N28: =IF($A28="","",M28/F28) | O28: =IF($A28="","",D28*(1-1/参数!$B$9)/(1-参数!$B$11-参数!$B$12)) | P28: =IF($A28="","",B28*(1-参数!$B$17)) | Q28: =IF($A28="","",P28/O28-1) | R28: =IF($A28="","",IF(P28<=O28,"插针触发强平","OK"))

Sheet 币本位滚仓
A1: 币本位滚仓明细
A2: 币本位逆向合约模型：保证金和盈亏以 TON 计，最终再按价格折算 USDT。下跌时保证金币价同步缩水，因此同等杠杆的强平距离通常比 U 本位更近。
A4: Step | B4: 起始价 | C4: 目标/结束价 | D4: 开仓执行价 | E4: 平仓执行价 | F4: 期初权益 TON | G4: 期初权益 USDT | H4: 名义仓位 USD | I4: 合约张数 | J4: 开仓费 TON | K4: 资金费 TON | L4: 毛盈亏 TON | M4: 平仓费 TON | N4: 期末权益 TON | O4: 期末权益 USDT | P4: 滚仓倍数 | Q4: 估算强平价 | R4: 段内插针低点 | S4: 强平缓冲 | T4: 状态
A5: =IF(ROW()-4<=参数!$B$8,ROW()-4,"") -> 1 | B5: =IF($A5="","",IF($A5=1,参数!$B$6,C4)) -> 1.5 | C5: =IF($A5="","",参数!$B$6*(参数!$B$7/参数!$B$6)^($A5/参数!$B$8)) -> 1.9720685 | D5: =IF($A5="","",B5*(1+参数!$B$14)) -> 1.5015 | E5: =IF($A5="","",C5*(1-参数!$B$14)) -> 1.9700964 | F5: =IF($A5="","",IF($A5=1,参数!$B$5/参数!$B$6,N4)) -> 6666.6667 | G5: =IF($A5="","",F5*B5) -> 10000 | H5: =IF($A5="","",G5*参数!$B$9) -> 25000 | I5: =IF($A5="","",H5/参数!$B$18) -> 25000 | J5: =IF($A5="","",H5*参数!$B$13/D5) -> 9.99001 | K5: =IF($A5="","",H5*参数!$B$15*参数!$B$16/((D5+E5)/2)) -> 4.3207788 | L5: =IF($A5="","",H5*(1/D5-1/E5)) -> 3960.2822 | M5: =IF($A5="","",H5*参数!$B$13/E5) -> 7.6138407 | N5: =IF($A5="","",MAX(0,F5+L5-J5-K5-M5)) -> 10605.024 | O5: =IF($A5="","",N5*C5) -> 20913.834 | P5: =IF($A5="","",O5/G5) -> 2.0913834 | Q5: =IF($A5="","",H5*(1+参数!$B$11+参数!$B$12)/(F5+H5/D5)) -> 1.0807712 | R5: =IF($A5="","",B5*(1-参数!$B$17)) -> 1.2 | S5: =IF($A5="","",R5/Q5-1) -> 0.11031825 | T5: =IF($A5="","",IF(R5<=Q5,"插针触发强平","OK")) -> OK
A6: =IF(ROW()-4<=参数!$B$8,ROW()-4,"") -> 2 | B6: =IF($A6="","",IF($A6=1,参数!$B$6,C5)) -> 1.9720685 | C6: =IF($A6="","",参数!$B$6*(参数!$B$7/参数!$B$6)^($A6/参数!$B$8)) -> 2.5927027 | D6: =IF($A6="","",B6*(1+参数!$B$14)) -> 1.9740405 | E6: =IF($A6="","",C6*(1-参数!$B$14)) -> 2.59011 | F6: =IF($A6="","",IF($A6=1,参数!$B$5/参数!$B$6,N5)) -> 10605.024 | G6: =IF($A6="","",F6*B6) -> 20913.834 | H6: =IF($A6="","",G6*参数!$B$9) -> 52284.585 | I6: =IF($A6="","",H6/参数!$B$18) -> 52284.585 | J6: =IF($A6="","",H6*参数!$B$13/D6) -> 15.891645 | K6: =IF($A6="","",H6*参数!$B$15*参数!$B$16/((D6+E6)/2)) -> 6.8732946 | L6: =IF($A6="","",H6*(1/D6-1/E6)) -> 6299.8333 | M6: =IF($A6="","",H6*参数!$B$13/E6) -> 12.111745 | N6: =IF($A6="","",MAX(0,F6+L6-J6-K6-M6)) -> 16869.981 | O6: =IF($A6="","",N6*C6) -> 43738.844 | P6: =IF($A6="","",O6/G6) -> 2.0913834 | Q6: =IF($A6="","",H6*(1+参数!$B$11+参数!$B$12)/(F6+H6/D6)) -> 1.4209032 | R6: =IF($A6="","",B6*(1-参数!$B$17)) -> 1.5776548 | S6: =IF($A6="","",R6/Q6-1) -> 0.11031825 | T6: =IF($A6="","",IF(R6<=Q6,"插针触发强平","OK")) -> OK
A7: =IF(ROW()-4<=参数!$B$8,ROW()-4,"") -> 3 | B7: =IF($A7="","",IF($A7=1,参数!$B$6,C6)) -> 2.5927027 | C7: =IF($A7="","",参数!$B$6*(参数!$B$7/参数!$B$6)^($A7/参数!$B$8)) -> 3.4086581 | D7: =IF($A7="","",B7*(1+参数!$B$14)) -> 2.5952954 | E7: =IF($A7="","",C7*(1-参数!$B$14)) -> 3.4052494 | F7: =IF($A7="","",IF($A7=1,参数!$B$5/参数!$B$6,N6)) -> 16869.981 | G7: =IF($A7="","",F7*B7) -> 43738.844 | H7: =IF($A7="","",G7*参数!$B$9) -> 109347.11 | I7: =IF($A7="","",H7/参数!$B$18) -> 109347.11 | J7: =IF($A7="","",H7*参数!$B$13/D7) -> 25.279692 | K7: =IF($A7="","",H7*参数!$B$15*参数!$B$16/((D7+E7)/2)) -> 10.933718 | L7: =IF($A7="","",H7*(1/D7-1/E7)) -> 10021.483 | M7: =IF($A7="","",H7*参数!$B$13/E7) -> 19.266802 | N7: =IF($A7="","",MAX(0,F7+L7-J7-K7-M7)) -> 26835.983 | O7: =IF($A7="","",N7*C7) -> 91474.692 | P7: =IF($A7="","",O7/G7) -> 2.0913834 | Q7: =IF($A7="","",H7*(1+参数!$B$11+参数!$B$12)/(F7+H7/D7)) -> 1.8680789 | R7: =IF($A7="","",B7*(1-参数!$B$17)) -> 2.0741621 | S7: =IF($A7="","",R7/Q7-1) -> 0.11031825 | T7: =IF($A7="","",IF(R7<=Q7,"插针触发强平","OK")) -> OK
A8: =IF(ROW()-4<=参数!$B$8,ROW()-4,"") -> 4 | B8: =IF($A8="","",IF($A8=1,参数!$B$6,C7)) -> 3.4086581 | C8: =IF($A8="","",参数!$B$6*(参数!$B$7/参数!$B$6)^($A8/参数!$B$8)) -> 4.4814047 | D8: =IF($A8="","",B8*(1+参数!$B$14)) -> 3.4120668 | E8: =IF($A8="","",C8*(1-参数!$B$14)) -> 4.4769233 | F8: =IF($A8="","",IF($A8=1,参数!$B$5/参数!$B$6,N7)) -> 26835.983 | G8: =IF($A8="","",F8*B8) -> 91474.692 | H8: =IF($A8="","",G8*参数!$B$9) -> 228686.73 | I8: =IF($A8="","",H8/参数!$B$18) -> 228686.73 | J8: =IF($A8="","",H8*参数!$B$13/D8) -> 40.213761 | K8: =IF($A8="","",H8*参数!$B$15*参数!$B$16/((D8+E8)/2)) -> 17.392852 | L8: =IF($A8="","",H8*(1/D8-1/E8)) -> 15941.71 | M8: =IF($A8="","",H8*参数!$B$13/E8) -> 30.648735 | N8: =IF($A8="","",MAX(0,F8+L8-J8-K8-M8)) -> 42689.438 | O8: =IF($A8="","",N8*C8) -> 191308.65 | P8: =IF($A8="","",O8/G8) -> 2.0913834 | Q8: =IF($A8="","",H8*(1+参数!$B$11+参数!$B$12)/(F8+H8/D8)) -> 2.4559864 | R8: =IF($A8="","",B8*(1-参数!$B$17)) -> 2.7269265 | S8: =IF($A8="","",R8/Q8-1) -> 0.11031825 | T8: =IF($A8="","",IF(R8<=Q8,"插针触发强平","OK")) -> OK
A9: =IF(ROW()-4<=参数!$B$8,ROW()-4,"") -> 5 | B9: =IF($A9="","",IF($A9=1,参数!$B$6,C8)) -> 4.4814047 | C9: =IF($A9="","",参数!$B$6*(参数!$B$7/参数!$B$6)^($A9/参数!$B$8)) -> 5.891758 | D9: =IF($A9="","",B9*(1+参数!$B$14)) -> 4.4858862 | E9: =IF($A9="","",C9*(1-参数!$B$14)) -> 5.8858662 | F9: =IF($A9="","",IF($A9=1,参数!$B$5/参数!$B$6,N8)) -> 42689.438 | G9: =IF($A9="","",F9*B9) -> 191308.65 | H9: =IF($A9="","",G9*参数!$B$9) -> 478271.63 | I9: =IF($A9="","",H9/参数!$B$18) -> 478271.63 | J9: =IF($A9="","",H9*参数!$B$13/D9) -> 63.970187 | K9: =IF($A9="","",H9*参数!$B$15*参数!$B$16/((D9+E9)/2)) -> 27.667743 | L9: =IF($A9="","",H9*(1/D9-1/E9)) -> 25359.333 | M9: =IF($A9="","",H9*参数!$B$13/E9) -> 48.754587 | N9: =IF($A9="","",MAX(0,F9+L9-J9-K9-M9)) -> 67908.379 | O9: =IF($A9="","",N9*C9) -> 400099.73 | P9: =IF($A9="","",O9/G9) -> 2.0913834 | Q9: =IF($A9="","",H9*(1+参数!$B$11+参数!$B$12)/(F9+H9/D9)) -> 3.2289155 | R9: =IF($A9="","",B9*(1-参数!$B$17)) -> 3.5851238 | S9: =IF($A9="","",R9/Q9-1) -> 0.11031825 | T9: =IF($A9="","",IF(R9<=Q9,"插针触发强平","OK")) -> OK
A10: =IF(ROW()-4<=参数!$B$8,ROW()-4,"") -> 6 | B10: =IF($A10="","",IF($A10=1,参数!$B$6,C9)) -> 5.891758 | C10: =IF($A10="","",参数!$B$6*(参数!$B$7/参数!$B$6)^($A10/参数!$B$8)) -> 7.7459667 | D10: =IF($A10="","",B10*(1+参数!$B$14)) -> 5.8976497 | E10: =IF($A10="","",C10*(1-参数!$B$14)) -> 7.7382207 | F10: =IF($A10="","",IF($A10=1,参数!$B$5/参数!$B$6,N9)) -> 67908.379 | G10: =IF($A10="","",F10*B10) -> 400099.73 | H10: =IF($A10="","",G10*参数!$B$9) -> 1000249.3 | I10: =IF($A10="","",H10/参数!$B$18) -> 1000249.3 | J10: =IF($A10="","",H10*参数!$B$13/D10) -> 101.76081 | K10: =IF($A10="","",H10*参数!$B$15*参数!$B$16/((D10+E10)/2)) -> 44.012563 | L10: =IF($A10="","",H10*(1/D10-1/E10)) -> 40340.452 | M10: =IF($A10="","",H10*参数!$B$13/E10) -> 77.556537 | N10: =IF($A10="","",MAX(0,F10+L10-J10-K10-M10)) -> 108025.5 | O10: =IF($A10="","",N10*C10) -> 836761.93 | P10: =IF($A10="","",O10/G10) -> 2.0913834 | Q10: =IF($A10="","",H10*(1+参数!$B$11+参数!$B$12)/(F10+H10/D10)) -> 4.2450949 | R10: =IF($A10="","",B10*(1-参数!$B$17)) -> 4.7134064 | S10: =IF($A10="","",R10/Q10-1) -> 0.11031825 | T10: =IF($A10="","",IF(R10<=Q10,"插针触发强平","OK")) -> OK
A11: =IF(ROW()-4<=参数!$B$8,ROW()-4,"") -> 7 | B11: =IF($A11="","",IF($A11=1,参数!$B$6,C10)) -> 7.7459667 | C11: =IF($A11="","",参数!$B$6*(参数!$B$7/参数!$B$6)^($A11/参数!$B$8)) -> 10.183718 | D11: =IF($A11="","",B11*(1+参数!$B$14)) -> 7.7537127 | E11: =IF($A11="","",C11*(1-参数!$B$14)) -> 10.173534 | F11: =IF($A11="","",IF($A11=1,参数!$B$5/参数!$B$6,N10)) -> 108025.5 | G11: =IF($A11="","",F11*B11) -> 836761.93 | H11: =IF($A11="","",G11*参数!$B$9) -> 2091904.8 | I11: =IF($A11="","",H11/参数!$B$18) -> 2091904.8 | J11: =IF($A11="","",H11*参数!$B$13/D11) -> 161.87638 | K11: =IF($A11="","",H11*参数!$B$15*参数!$B$16/((D11+E11)/2)) -> 70.013144 | L11: =IF($A11="","",H11*(1/D11-1/E11)) -> 64171.721 | M11: =IF($A11="","",H11*参数!$B$13/E11) -> 123.37334 | N11: =IF($A11="","",MAX(0,F11+L11-J11-K11-M11)) -> 171841.96 | O11: =IF($A11="","",N11*C11) -> 1749990 | P11: =IF($A11="","",O11/G11) -> 2.0913834 | Q11: =IF($A11="","",H11*(1+参数!$B$11+参数!$B$12)/(F11+H11/D11)) -> 5.5810785 | R11: =IF($A11="","",B11*(1-参数!$B$17)) -> 6.1967734 | S11: =IF($A11="","",R11/Q11-1) -> 0.11031825 | T11: =IF($A11="","",IF(R11<=Q11,"插针触发强平","OK")) -> OK
A12: =IF(ROW()-4<=参数!$B$8,ROW()-4,"") -> 8 | B12: =IF($A12="","",IF($A12=1,参数!$B$6,C11)) -> 10.183718 | C12: =IF($A12="","",参数!$B$6*(参数!$B$7/参数!$B$6)^($A12/参数!$B$8)) -> 13.388659 | D12: =IF($A12="","",B12*(1+参数!$B$14)) -> 10.193901 | E12: =IF($A12="","",C12*(1-参数!$B$14)) -> 13.37527 | F12: =IF($A12="","",IF($A12=1,参数!$B$5/参数!$B$6,N11)) -> 171841.96 | G12: =IF($A12="","",F12*B12) -> 1749990 | H12: =IF($A12="","",G12*参数!$B$9) -> 4374975 | I12: =IF($A12="","",H12/参数!$B$18) -> 4374975 | J12: =IF($A12="","",H12*参数!$B$13/D12) -> 257.50543 | K12: =IF($A12="","",H12*参数!$B$15*参数!$B$16/((D12+E12)/2)) -> 111.37366 | L12: =IF($A12="","",H12*(1/D12-1/E12)) -> 102081.4 | M12: =IF($A12="","",H12*参数!$B$13/E12) -> 196.25659 | N12: =IF($A12="","",MAX(0,F12+L12-J12-K12-M12)) -> 273358.22 | O12: =IF($A12="","",N12*C12) -> 3659900 | P12: =IF($A12="","",O12/G12) -> 2.0913834 | Q12: =IF($A12="","",H12*(1+参数!$B$11+参数!$B$12)/(F12+H12/D12)) -> 7.3375126 | R12: =IF($A12="","",B12*(1-参数!$B$17)) -> 8.1469742 | S12: =IF($A12="","",R12/Q12-1) -> 0.11031825 | T12: =IF($A12="","",IF(R12<=Q12,"插针触发强平","OK")) -> OK
A13: =IF(ROW()-4<=参数!$B$8,ROW()-4,"") -> 9 | B13: =IF($A13="","",IF($A13=1,参数!$B$6,C12)) -> 13.388659 | C13: =IF($A13="","",参数!$B$6*(参数!$B$7/参数!$B$6)^($A13/参数!$B$8)) -> 17.602235 | D13: =IF($A13="","",B13*(1+参数!$B$14)) -> 13.402048 | E13: =IF($A13="","",C13*(1-参数!$B$14)) -> 17.584633 | F13: =IF($A13="","",IF($A13=1,参数!$B$5/参数!$B$6,N12)) -> 273358.22 | G13: =IF($A13="","",F13*B13) -> 3659900 | H13: =IF($A13="","",G13*参数!$B$9) -> 9149750 | I13: =IF($A13="","",H13/参数!$B$18) -> 9149750 | J13: =IF($A13="","",H13*参数!$B$13/D13) -> 409.6277 | K13: =IF($A13="","",H13*参数!$B$15*参数!$B$16/((D13+E13)/2)) -> 177.16806 | L13: =IF($A13="","",H13*(1/D13-1/E13)) -> 162386.35 | M13: =IF($A13="","",H13*参数!$B$13/E13) -> 312.19589 | N13: =IF($A13="","",MAX(0,F13+L13-J13-K13-M13)) -> 434845.58 | O13: =IF($A13="","",N13*C13) -> 7654254 | P13: =IF($A13="","",O13/G13) -> 2.0913834 | Q13: =IF($A13="","",H13*(1+参数!$B$11+参数!$B$12)/(F13+H13/D13)) -> 9.6467181 | R13: =IF($A13="","",B13*(1-参数!$B$17)) -> 10.710927 | S13: =IF($A13="","",R13/Q13-1) -> 0.11031825 | T13: =IF($A13="","",IF(R13<=Q13,"插针触发强平","OK")) -> OK
A14: =IF(ROW()-4<=参数!$B$8,ROW()-4,"") -> 10 | B14: =IF($A14="","",IF($A14=1,参数!$B$6,C13)) -> 17.602235 | C14: =IF($A14="","",参数!$B$6*(参数!$B$7/参数!$B$6)^($A14/参数!$B$8)) -> 23.141875 | D14: =IF($A14="","",B14*(1+参数!$B$14)) -> 17.619837 | E14: =IF($A14="","",C14*(1-参数!$B$14)) -> 23.118733 | F14: =IF($A14="","",IF($A14=1,参数!$B$5/参数!$B$6,N13)) -> 434845.58 | G14: =IF($A14="","",F14*B14) -> 7654254 | H14: =IF($A14="","",G14*参数!$B$9) -> 19135635 | I14: =IF($A14="","",H14/参数!$B$18) -> 19135635 | J14: =IF($A14="","",H14*参数!$B$13/D14) -> 651.61676 | K14: =IF($A14="","",H14*参数!$B$15*参数!$B$16/((D14+E14)/2)) -> 281.83074 | L14: =IF($A14="","",H14*(1/D14-1/E14)) -> 258316.68 | M14: =IF($A14="","",H14*参数!$B$13/E14) -> 496.62675 | N14: =IF($A14="","",MAX(0,F14+L14-J14-K14-M14)) -> 691732.19 | O14: =IF($A14="","",N14*C14) -> 16007980 | P14: =IF($A14="","",O14/G14) -> 2.0913834 | Q14: =IF($A14="","",H14*(1+参数!$B$11+参数!$B$12)/(F14+H14/D14)) -> 12.682659 | R14: =IF($A14="","",B14*(1-参数!$B$17)) -> 14.081788 | S14: =IF($A14="","",R14/Q14-1) -> 0.11031825 | T14: =IF($A14="","",IF(R14<=Q14,"插针触发强平","OK")) -> OK
A15: =IF(ROW()-4<=参数!$B$8,ROW()-4,"") -> 11 | B15: =IF($A15="","",IF($A15=1,参数!$B$6,C14)) -> 23.141875 | C15: =IF($A15="","",参数!$B$6*(参数!$B$7/参数!$B$6)^($A15/参数!$B$8)) -> 30.424907 | D15: =IF($A15="","",B15*(1+参数!$B$14)) -> 23.165016 | E15: =IF($A15="","",C15*(1-参数!$B$14)) -> 30.394482 | F15: =IF($A15="","",IF($A15=1,参数!$B$5/参数!$B$6,N14)) -> 691732.19 | G15: =IF($A15="","",F15*B15) -> 16007980 | H15: =IF($A15="","",G15*参数!$B$9) -> 40019949 | I15: =IF($A15="","",H15/参数!$B$18) -> 40019949 | J15: =IF($A15="","",H15*参数!$B$13/D15) -> 1036.5617 | K15: =IF($A15="","",H15*参数!$B$15*参数!$B$16/((D15+E15)/2)) -> 448.32327 | L15: =IF($A15="","",H15*(1/D15-1/E15)) -> 410918.21 | M15: =IF($A15="","",H15*参数!$B$13/E15) -> 790.01081 | N15: =IF($A15="","",MAX(0,F15+L15-J15-K15-M15)) -> 1100375.5 | O15: =IF($A15="","",N15*C15) -> 33478823 | P15: =IF($A15="","",O15/G15) -> 2.0913834 | Q15: =IF($A15="","",H15*(1+参数!$B$11+参数!$B$12)/(F15+H15/D15)) -> 16.674048 | R15: =IF($A15="","",B15*(1-参数!$B$17)) -> 18.5135 | S15: =IF($A15="","",R15/Q15-1) -> 0.11031825 | T15: =IF($A15="","",IF(R15<=Q15,"插针触发强平","OK")) -> OK
A16: =IF(ROW()-4<=参数!$B$8,ROW()-4,"") -> 12 | B16: =IF($A16="","",IF($A16=1,参数!$B$6,C15)) -> 30.424907 | C16: =IF($A16="","",参数!$B$6*(参数!$B$7/参数!$B$6)^($A16/参数!$B$8)) -> 40 | D16: =IF($A16="","",B16*(1+参数!$B$14)) -> 30.455332 | E16: =IF($A16="","",C16*(1-参数!$B$14)) -> 39.96 | F16: =IF($A16="","",IF($A16=1,参数!$B$5/参数!$B$6,N15)) -> 1100375.5 | G16: =IF($A16="","",F16*B16) -> 33478823 | H16: =IF($A16="","",G16*参数!$B$9) -> 83697057 | I16: =IF($A16="","",H16/参数!$B$18) -> 83697057 | J16: =IF($A16="","",H16*参数!$B$13/D16) -> 1648.9143 | K16: =IF($A16="","",H16*参数!$B$15*参数!$B$16/((D16+E16)/2)) -> 713.17187 | L16: =IF($A16="","",H16*(1/D16-1/E16)) -> 653669.63 | M16: =IF($A16="","",H16*参数!$B$13/E16) -> 1256.7126 | N16: =IF($A16="","",MAX(0,F16+L16-J16-K16-M16)) -> 1750426.3 | O16: =IF($A16="","",N16*C16) -> 70017053 | P16: =IF($A16="","",O16/G16) -> 2.0913834 | Q16: =IF($A16="","",H16*(1+参数!$B$11+参数!$B$12)/(F16+H16/D16)) -> 21.921576 | R16: =IF($A16="","",B16*(1-参数!$B$17)) -> 24.339926 | S16: =IF($A16="","",R16/Q16-1) -> 0.11031825 | T16: =IF($A16="","",IF(R16<=Q16,"插针触发强平","OK")) -> OK
... A28: =IF(ROW()-4<=参数!$B$8,ROW()-4,"") | B28: =IF($A28="","",IF($A28=1,参数!$B$6,C27)) | C28: =IF($A28="","",参数!$B$6*(参数!$B$7/参数!$B$6)^($A28/参数!$B$8)) | D28: =IF($A28="","",B28*(1+参数!$B$14)) | E28: =IF($A28="","",C28*(1-参数!$B$14)) | F28: =IF($A28="","",IF($A28=1,参数!$B$5/参数!$B$6,N27)) | G28: =IF($A28="","",F28*B28) | H28: =IF($A28="","",G28*参数!$B$9) | I28: =IF($A28="","",H28/参数!$B$18) | J28: =IF($A28="","",H28*参数!$B$13/D28) | K28: =IF($A28="","",H28*参数!$B$15*参数!$B$16/((D28+E28)/2)) | L28: =IF($A28="","",H28*(1/D28-1/E28)) | M28: =IF($A28="","",H28*参数!$B$13/E28) | N28: =IF($A28="","",MAX(0,F28+L28-J28-K28-M28)) | O28: =IF($A28="","",N28*C28) | P28: =IF($A28="","",O28/G28) | Q28: =IF($A28="","",H28*(1+参数!$B$11+参数!$B$12)/(F28+H28/D28)) | R28: =IF($A28="","",B28*(1-参数!$B$17)) | S28: =IF($A28="","",R28/Q28-1) | T28: =IF($A28="","",IF(R28<=Q28,"插针触发强平","OK"))

Sheet 风险预算滚仓
A1: 风险预算式滚仓
A2: 对应你图里的口径：趋势中只拿总权益的一部分作为单次保证金，单笔止损控制总资金风险；上涨后再加趋势仓，并观察旧仓浮盈能否覆盖新仓风险。
A4: 加仓次序 | B4: 触发/开仓价 | C4: 开仓执行价 | D4: 期初权益 | E4: 单次保证金 | F4: 单笔杠杆 | G4: 新增名义仓位 | H4: 新增持币数 | I4: 开仓费 | J4: 累计持币数 | K4: 累计开仓费 | L4: 组合名义仓位 | M4: 组合杠杆 | N4: 新仓止损价 | O4: 新仓风险额 | P4: 新仓风险/权益 | Q4: 旧仓浮盈 | R4: 目标价权益 | S4: 状态
A5: =IF(ROW()-4<=参数!$B$29,ROW()-4,"") -> 1 | B5: =IF($A5="","",参数!$B$6*(1+参数!$B$28)^($A5-1)) -> 1.5 | C5: =IF($A5="","",B5*(1+参数!$B$14)) -> 1.5015 | D5: =IF($A5="","",参数!$B$5) -> 10000 | E5: =IF($A5="","",D5*参数!$B$25) -> 1000 | F5: =IF($A5="","",参数!$B$26) -> 10 | G5: =IF($A5="","",E5*F5) -> 10000 | H5: =IF($A5="","",G5/C5) -> 6660.0067 | I5: =IF($A5="","",G5*参数!$B$13) -> 6 | J5: =IF($A5="","",SUM($H$5:H5)) -> 6660.0067 | K5: =IF($A5="","",SUM($I$5:I5)) -> 6 | L5: =IF($A5="","",J5*B5) -> 9990.01 | M5: =IF($A5="","",L5/MAX(1,D5)) -> 0.999001 | N5: =IF($A5="","",C5*(1-参数!$B$27)) -> 1.47147 | O5: =IF($A5="","",H5*(C5-N5)+H5*N5*参数!$B$13+I5) -> 211.88 | P5: =IF($A5="","",O5/D5) -> 0.021188 | Q5: =IF($A5="", "", 0) -> 0 | R5: =IF($A5="","",参数!$B$5+SUM($H$5:H5)*参数!$B$7-SUMPRODUCT($H$5:H5,$C$5:C5)-K5-SUM($H$5:H5)*参数!$B$7*参数!$B$13) -> 266234.43 | S5: =IF($A5="","",IF(P5>0.03,"风险偏高",IF(Q5<O5,"旧仓浮盈不足","OK"))) -> 旧仓浮盈不足
A6: =IF(ROW()-4<=参数!$B$29,ROW()-4,"") -> 2 | B6: =IF($A6="","",参数!$B$6*(1+参数!$B$28)^($A6-1)) -> 1.65 | C6: =IF($A6="","",B6*(1+参数!$B$14)) -> 1.65165 | D6: =IF($A6="","",参数!$B$5+SUM($H$5:H5)*B6-SUMPRODUCT($H$5:H5,$C$5:C5)-K5) -> 10983.011 | E6: =IF($A6="","",D6*参数!$B$25) -> 1098.3011 | F6: =IF($A6="","",参数!$B$26) -> 10 | G6: =IF($A6="","",E6*F6) -> 10983.011 | H6: =IF($A6="","",G6/C6) -> 6649.7206 | I6: =IF($A6="","",G6*参数!$B$13) -> 6.5898066 | J6: =IF($A6="","",SUM($H$5:H6)) -> 13309.727 | K6: =IF($A6="","",SUM($I$5:I6)) -> 12.589807 | L6: =IF($A6="","",J6*B6) -> 21961.05 | M6: =IF($A6="","",L6/MAX(1,D6)) -> 1.9995473 | N6: =IF($A6="","",C6*(1-参数!$B$27)) -> 1.618617 | O6: =IF($A6="","",H6*(C6-N6)+H6*N6*参数!$B$13+I6) -> 232.70804 | P6: =IF($A6="","",O6/D6) -> 0.021188 | Q6: =IF($A6="","",SUM($H$5:H5)*B6-SUMPRODUCT($H$5:H5,$C$5:C5)-K5) -> 983.01099 | R6: =IF($A6="","",参数!$B$5+SUM($H$5:H6)*参数!$B$7-SUMPRODUCT($H$5:H6,$C$5:C6)-K6-SUM($H$5:H6)*参数!$B$7*参数!$B$13) -> 521074.06 | S6: =IF($A6="","",IF(P6>0.03,"风险偏高",IF(Q6<O6,"旧仓浮盈不足","OK"))) -> OK
A7: =IF(ROW()-4<=参数!$B$29,ROW()-4,"") -> 3 | B7: =IF($A7="","",参数!$B$6*(1+参数!$B$28)^($A7-1)) -> 1.815 | C7: =IF($A7="","",B7*(1+参数!$B$14)) -> 1.816815 | D7: =IF($A7="","",参数!$B$5+SUM($H$5:H6)*B7-SUMPRODUCT($H$5:H6,$C$5:C6)-K6) -> 13161.554 | E7: =IF($A7="","",D7*参数!$B$25) -> 1316.1554 | F7: =IF($A7="","",参数!$B$26) -> 10 | G7: =IF($A7="","",E7*F7) -> 13161.554 | H7: =IF($A7="","",G7/C7) -> 7244.3007 | I7: =IF($A7="","",G7*参数!$B$13) -> 7.8969325 | J7: =IF($A7="","",SUM($H$5:H7)) -> 20554.028 | K7: =IF($A7="","",SUM($I$5:I7)) -> 20.486739 | L7: =IF($A7="","",J7*B7) -> 37305.561 | M7: =IF($A7="","",L7/MAX(1,D7)) -> 2.8344343 | N7: =IF($A7="","",C7*(1-参数!$B$27)) -> 1.7804787 | O7: =IF($A7="","",H7*(C7-N7)+H7*N7*参数!$B$13+I7) -> 278.86701 | P7: =IF($A7="","",O7/D7) -> 0.021188 | Q7: =IF($A7="","",SUM($H$5:H6)*B7-SUMPRODUCT($H$5:H6,$C$5:C6)-K6) -> 3161.5541 | R7: =IF($A7="","",参数!$B$5+SUM($H$5:H7)*参数!$B$7-SUMPRODUCT($H$5:H7,$C$5:C7)-K7-SUM($H$5:H7)*参数!$B$7*参数!$B$13) -> 797502.77 | S7: =IF($A7="","",IF(P7>0.03,"风险偏高",IF(Q7<O7,"旧仓浮盈不足","OK"))) -> OK
A8: =IF(ROW()-4<=参数!$B$29,ROW()-4,"") -> 4 | B8: =IF($A8="","",参数!$B$6*(1+参数!$B$28)^($A8-1)) -> 1.9965 | C8: =IF($A8="","",B8*(1+参数!$B$14)) -> 1.9984965 | D8: =IF($A8="","",参数!$B$5+SUM($H$5:H7)*B8-SUMPRODUCT($H$5:H7,$C$5:C7)-K7) -> 16871.065 | E8: =IF($A8="","",D8*参数!$B$25) -> 1687.1065 | F8: =IF($A8="","",参数!$B$26) -> 10 | G8: =IF($A8="","",E8*F8) -> 16871.065 | H8: =IF($A8="","",G8/C8) -> 8441.8786 | I8: =IF($A8="","",G8*参数!$B$13) -> 10.122639 | J8: =IF($A8="","",SUM($H$5:H8)) -> 28995.907 | K8: =IF($A8="","",SUM($I$5:I8)) -> 30.609378 | L8: =IF($A8="","",J8*B8) -> 57890.327 | M8: =IF($A8="","",L8/MAX(1,D8)) -> 3.4313381 | N8: =IF($A8="","",C8*(1-参数!$B$27)) -> 1.9585266 | O8: =IF($A8="","",H8*(C8-N8)+H8*N8*参数!$B$13+I8) -> 357.46412 | P8: =IF($A8="","",O8/D8) -> 0.021188 | Q8: =IF($A8="","",SUM($H$5:H7)*B8-SUMPRODUCT($H$5:H7,$C$5:C7)-K7) -> 6871.0649 | R8: =IF($A8="","",参数!$B$5+SUM($H$5:H8)*参数!$B$7-SUMPRODUCT($H$5:H8,$C$5:C8)-K8-SUM($H$5:H8)*参数!$B$7*参数!$B$13) -> 1118094.1 | S8: =IF($A8="","",IF(P8>0.03,"风险偏高",IF(Q8<O8,"旧仓浮盈不足","OK"))) -> OK
A9: =IF(ROW()-4<=参数!$B$29,ROW()-4,"") -> 5 | B9: =IF($A9="","",参数!$B$6*(1+参数!$B$28)^($A9-1)) -> 2.19615 | C9: =IF($A9="","",B9*(1+参数!$B$14)) -> 2.1983462 | D9: =IF($A9="","",参数!$B$5+SUM($H$5:H8)*B9-SUMPRODUCT($H$5:H8,$C$5:C8)-K8) -> 22633.121 | E9: =IF($A9="","",D9*参数!$B$25) -> 2263.3121 | F9: =IF($A9="","",参数!$B$26) -> 10 | G9: =IF($A9="","",E9*F9) -> 22633.121 | H9: =IF($A9="","",G9/C9) -> 10295.522 | I9: =IF($A9="","",G9*参数!$B$13) -> 13.579872 | J9: =IF($A9="","",SUM($H$5:H9)) -> 39291.428 | K9: =IF($A9="","",SUM($I$5:I9)) -> 44.18925 | L9: =IF($A9="","",J9*B9) -> 86289.87 | M9: =IF($A9="","",L9/MAX(1,D9)) -> 3.8125485 | N9: =IF($A9="","",C9*(1-参数!$B$27)) -> 2.1543792 | O9: =IF($A9="","",H9*(C9-N9)+H9*N9*参数!$B$13+I9) -> 479.55056 | P9: =IF($A9="","",O9/D9) -> 0.021188 | Q9: =IF($A9="","",SUM($H$5:H8)*B9-SUMPRODUCT($H$5:H8,$C$5:C8)-K8) -> 12633.121 | R9: =IF($A9="","",参数!$B$5+SUM($H$5:H9)*参数!$B$7-SUMPRODUCT($H$5:H9,$C$5:C9)-K9-SUM($H$5:H9)*参数!$B$7*参数!$B$13) -> 1507021.2 | S9: =IF($A9="","",IF(P9>0.03,"风险偏高",IF(Q9<O9,"旧仓浮盈不足","OK"))) -> OK
A10: =IF(ROW()-4<=参数!$B$29,ROW()-4,"") -> 6 | B10: =IF($A10="","",参数!$B$6*(1+参数!$B$28)^($A10-1)) -> 2.415765 | C10: =IF($A10="","",B10*(1+参数!$B$14)) -> 2.4181808 | D10: =IF($A10="","",参数!$B$5+SUM($H$5:H9)*B10-SUMPRODUCT($H$5:H9,$C$5:C9)-K9) -> 31225.917 | E10: =IF($A10="","",D10*参数!$B$25) -> 3122.5917 | F10: =IF($A10="","",参数!$B$26) -> 10 | G10: =IF($A10="","",E10*F10) -> 31225.917 | H10: =IF($A10="","",G10/C10) -> 12912.979 | I10: =IF($A10="","",G10*参数!$B$13) -> 18.73555 | J10: =IF($A10="","",SUM($H$5:H10)) -> 52204.407 | K10: =IF($A10="","",SUM($I$5:I10)) -> 62.924801 | L10: =IF($A10="","",J10*B10) -> 126113.58 | M10: =IF($A10="","",L10/MAX(1,D10)) -> 4.038747 | N10: =IF($A10="","",C10*(1-参数!$B$27)) -> 2.3698171 | O10: =IF($A10="","",H10*(C10-N10)+H10*N10*参数!$B$13+I10) -> 661.61474 | P10: =IF($A10="","",O10/D10) -> 0.021188 | Q10: =IF($A10="","",SUM($H$5:H9)*B10-SUMPRODUCT($H$5:H9,$C$5:C9)-K9) -> 21225.917 | R10: =IF($A10="","",参数!$B$5+SUM($H$5:H10)*参数!$B$7-SUMPRODUCT($H$5:H10,$C$5:C10)-K10-SUM($H$5:H10)*参数!$B$7*参数!$B$13) -> 1991985.8 | S10: =IF($A10="","",IF(P10>0.03,"风险偏高",IF(Q10<O10,"旧仓浮盈不足","OK"))) -> OK
A11: =IF(ROW()-4<=参数!$B$29,ROW()-4,"") -> 7 | B11: =IF($A11="","",参数!$B$6*(1+参数!$B$28)^($A11-1)) -> 2.6573415 | C11: =IF($A11="","",B11*(1+参数!$B$14)) -> 2.6599988 | D11: =IF($A11="","",参数!$B$5+SUM($H$5:H10)*B11-SUMPRODUCT($H$5:H10,$C$5:C10)-K10) -> 43787.345 | E11: =IF($A11="","",D11*参数!$B$25) -> 4378.7345 | F11: =IF($A11="","",参数!$B$26) -> 10 | G11: =IF($A11="","",E11*F11) -> 43787.345 | H11: =IF($A11="","",G11/C11) -> 16461.415 | I11: =IF($A11="","",G11*参数!$B$13) -> 26.272407 | J11: =IF($A11="","",SUM($H$5:H11)) -> 68665.822 | K11: =IF($A11="","",SUM($I$5:I11)) -> 89.197208 | L11: =IF($A11="","",J11*B11) -> 182468.54 | M11: =IF($A11="","",L11/MAX(1,D11)) -> 4.1671524 | N11: =IF($A11="","",C11*(1-参数!$B$27)) -> 2.6067989 | O11: =IF($A11="","",H11*(C11-N11)+H11*N11*参数!$B$13+I11) -> 927.76627 | P11: =IF($A11="","",O11/D11) -> 0.021188 | Q11: =IF($A11="","",SUM($H$5:H10)*B11-SUMPRODUCT($H$5:H10,$C$5:C10)-K10) -> 33787.345 | R11: =IF($A11="","",参数!$B$5+SUM($H$5:H11)*参数!$B$7-SUMPRODUCT($H$5:H11,$C$5:C11)-K11-SUM($H$5:H11)*参数!$B$7*参数!$B$13) -> 2606233.7 | S11: =IF($A11="","",IF(P11>0.03,"风险偏高",IF(Q11<O11,"旧仓浮盈不足","OK"))) -> OK
A12: =IF(ROW()-4<=参数!$B$29,ROW()-4,"") -> 8 | B12: =IF($A12="","",参数!$B$6*(1+参数!$B$28)^($A12-1)) -> 2.9230757 | C12: =IF($A12="","",B12*(1+参数!$B$14)) -> 2.9259987 | D12: =IF($A12="","",参数!$B$5+SUM($H$5:H11)*B12-SUMPRODUCT($H$5:H11,$C$5:C11)-K11) -> 61964.183 | E12: =IF($A12="","",D12*参数!$B$25) -> 6196.4183 | F12: =IF($A12="","",参数!$B$26) -> 10 | G12: =IF($A12="","",E12*F12) -> 61964.183 | H12: =IF($A12="","",G12/C12) -> 21177.105 | I12: =IF($A12="","",G12*参数!$B$13) -> 37.17851 | J12: =IF($A12="","",SUM($H$5:H12)) -> 89842.928 | K12: =IF($A12="","",SUM($I$5:I12)) -> 126.37572 | L12: =IF($A12="","",J12*B12) -> 262617.67 | M12: =IF($A12="","",L12/MAX(1,D12)) -> 4.2382173 | N12: =IF($A12="","",C12*(1-参数!$B$27)) -> 2.8674788 | O12: =IF($A12="","",H12*(C12-N12)+H12*N12*参数!$B$13+I12) -> 1312.8971 | P12: =IF($A12="","",O12/D12) -> 0.021188 | Q12: =IF($A12="","",SUM($H$5:H11)*B12-SUMPRODUCT($H$5:H11,$C$5:C11)-K11) -> 51964.183 | R12: =IF($A12="","",参数!$B$5+SUM($H$5:H12)*参数!$B$7-SUMPRODUCT($H$5:H12,$C$5:C12)-K12-SUM($H$5:H12)*参数!$B$7*参数!$B$13) -> 3390808.3 | S12: =IF($A12="","",IF(P12>0.03,"风险偏高",IF(Q12<O12,"旧仓浮盈不足","OK"))) -> OK
A13: =IF(ROW()-4<=参数!$B$29,ROW()-4,"") | B13: =IF($A13="","",参数!$B$6*(1+参数!$B$28)^($A13-1)) | C13: =IF($A13="","",B13*(1+参数!$B$14)) | D13: =IF($A13="","",参数!$B$5+SUM($H$5:H12)*B13-SUMPRODUCT($H$5:H12,$C$5:C12)-K12) | E13: =IF($A13="","",D13*参数!$B$25) | F13: =IF($A13="","",参数!$B$26) | G13: =IF($A13="","",E13*F13) | H13: =IF($A13="","",G13/C13) | I13: =IF($A13="","",G13*参数!$B$13) | J13: =IF($A13="","",SUM($H$5:H13)) | K13: =IF($A13="","",SUM($I$5:I13)) | L13: =IF($A13="","",J13*B13) | M13: =IF($A13="","",L13/MAX(1,D13)) | N13: =IF($A13="","",C13*(1-参数!$B$27)) | O13: =IF($A13="","",H13*(C13-N13)+H13*N13*参数!$B$13+I13) | P13: =IF($A13="","",O13/D13) | Q13: =IF($A13="","",SUM($H$5:H12)*B13-SUMPRODUCT($H$5:H12,$C$5:C12)-K12) | R13: =IF($A13="","",参数!$B$5+SUM($H$5:H13)*参数!$B$7-SUMPRODUCT($H$5:H13,$C$5:C13)-K13-SUM($H$5:H13)*参数!$B$7*参数!$B$13) | S13: =IF($A13="","",IF(P13>0.03,"风险偏高",IF(Q13<O13,"旧仓浮盈不足","OK")))
A14: =IF(ROW()-4<=参数!$B$29,ROW()-4,"") | B14: =IF($A14="","",参数!$B$6*(1+参数!$B$28)^($A14-1)) | C14: =IF($A14="","",B14*(1+参数!$B$14)) | D14: =IF($A14="","",参数!$B$5+SUM($H$5:H13)*B14-SUMPRODUCT($H$5:H13,$C$5:C13)-K13) | E14: =IF($A14="","",D14*参数!$B$25) | F14: =IF($A14="","",参数!$B$26) | G14: =IF($A14="","",E14*F14) | H14: =IF($A14="","",G14/C14) | I14: =IF($A14="","",G14*参数!$B$13) | J14: =IF($A14="","",SUM($H$5:H14)) | K14: =IF($A14="","",SUM($I$5:I14)) | L14: =IF($A14="","",J14*B14) | M14: =IF($A14="","",L14/MAX(1,D14)) | N14: =IF($A14="","",C14*(1-参数!$B$27)) | O14: =IF($A14="","",H14*(C14-N14)+H14*N14*参数!$B$13+I14) | P14: =IF($A14="","",O14/D14) | Q14: =IF($A14="","",SUM($H$5:H13)*B14-SUMPRODUCT($H$5:H13,$C$5:C13)-K13) | R14: =IF($A14="","",参数!$B$5+SUM($H$5:H14)*参数!$B$7-SUMPRODUCT($H$5:H14,$C$5:C14)-K14-SUM($H$5:H14)*参数!$B$7*参数!$B$13) | S14: =IF($A14="","",IF(P14>0.03,"风险偏高",IF(Q14<O14,"旧仓浮盈不足","OK")))
A15: =IF(ROW()-4<=参数!$B$29,ROW()-4,"") | B15: =IF($A15="","",参数!$B$6*(1+参数!$B$28)^($A15-1)) | C15: =IF($A15="","",B15*(1+参数!$B$14)) | D15: =IF($A15="","",参数!$B$5+SUM($H$5:H14)*B15-SUMPRODUCT($H$5:H14,$C$5:C14)-K14) | E15: =IF($A15="","",D15*参数!$B$25) | F15: =IF($A15="","",参数!$B$26) | G15: =IF($A15="","",E15*F15) | H15: =IF($A15="","",G15/C15) | I15: =IF($A15="","",G15*参数!$B$13) | J15: =IF($A15="","",SUM($H$5:H15)) | K15: =IF($A15="","",SUM($I$5:I15)) | L15: =IF($A15="","",J15*B15) | M15: =IF($A15="","",L15/MAX(1,D15)) | N15: =IF($A15="","",C15*(1-参数!$B$27)) | O15: =IF($A15="","",H15*(C15-N15)+H15*N15*参数!$B$13+I15) | P15: =IF($A15="","",O15/D15) | Q15: =IF($A15="","",SUM($H$5:H14)*B15-SUMPRODUCT($H$5:H14,$C$5:C14)-K14) | R15: =IF($A15="","",参数!$B$5+SUM($H$5:H15)*参数!$B$7-SUMPRODUCT($H$5:H15,$C$5:C15)-K15-SUM($H$5:H15)*参数!$B$7*参数!$B$13) | S15: =IF($A15="","",IF(P15>0.03,"风险偏高",IF(Q15<O15,"旧仓浮盈不足","OK")))
A16: =IF(ROW()-4<=参数!$B$29,ROW()-4,"") | B16: =IF($A16="","",参数!$B$6*(1+参数!$B$28)^($A16-1)) | C16: =IF($A16="","",B16*(1+参数!$B$14)) | D16: =IF($A16="","",参数!$B$5+SUM($H$5:H15)*B16-SUMPRODUCT($H$5:H15,$C$5:C15)-K15) | E16: =IF($A16="","",D16*参数!$B$25) | F16: =IF($A16="","",参数!$B$26) | G16: =IF($A16="","",E16*F16) | H16: =IF($A16="","",G16/C16) | I16: =IF($A16="","",G16*参数!$B$13) | J16: =IF($A16="","",SUM($H$5:H16)) | K16: =IF($A16="","",SUM($I$5:I16)) | L16: =IF($A16="","",J16*B16) | M16: =IF($A16="","",L16/MAX(1,D16)) | N16: =IF($A16="","",C16*(1-参数!$B$27)) | O16: =IF($A16="","",H16*(C16-N16)+H16*N16*参数!$B$13+I16) | P16: =IF($A16="","",O16/D16) | Q16: =IF($A16="","",SUM($H$5:H15)*B16-SUMPRODUCT($H$5:H15,$C$5:C15)-K15) | R16: =IF($A16="","",参数!$B$5+SUM($H$5:H16)*参数!$B$7-SUMPRODUCT($H$5:H16,$C$5:C16)-K16-SUM($H$5:H16)*参数!$B$7*参数!$B$13) | S16: =IF($A16="","",IF(P16>0.03,"风险偏高",IF(Q16<O16,"旧仓浮盈不足","OK")))
A19: 定义说明
A20: 这个页的“滚仓”不是每次把全部权益打满目标杠杆，而是把总权益拆成多笔风险预算。每次只投入一小部分保证金，单笔亏损用止损幅度控制。

Sheet 目标币仓降杠杆
A1: 目标币仓降杠杆模式
A2: 对应截图里的思路：价格上涨后，利润折算成币本位本金；本金变大后，逐步降低杠杆，目标是维持一个较大的币数量仓位，而不是一直保持固定高杠杆。黄色列可手动改。
A4: Step | B4: 本段涨幅 | C4: TON单价 | D4: 币本位本金 | E4: 手动杠杆 | F4: 自动目标杠杆 | G4: 使用杠杆 | H4: 维持仓位(TON) | I4: 本段币本位收益 | J4: 资产总额U | K4: 估算强平价 | L4: 到强平回撤 | M4: 安全杠杆上限 | N4: 状态
A5: 0 | B5: 0 | C5: =参数!$B$6 -> 1.5 | D5: =参数!$B$5/参数!$B$6 -> 6666.6667 | E5: 10 | F5: =IF(D5=0,"",(参数!$B$5/参数!$B$6*参数!$B$26)/D5) -> 10 | G5: =IF(E5="",F5,E5) -> 10 | H5: =D5*G5 -> 66666.667 | I5: =0 -> 0 | J5: =D5*C5 -> 10000 | K5: =IF(G5=0,"",C5*(1-1/G5)/(1-参数!$B$11-参数!$B$12)) -> 1.3608871 | L5: =IF(K5="","",1-K5/C5) -> 0.092741935 | M5: =参数!$B$21 -> 2.8153153 | N5: =IF(G5>M5,"超过安全杠杆",IF(L5<参数!$B$17,"插针风险","OK")) -> 超过安全杠杆
A6: 1 | B6: 0.04 | C6: =C5*(1+B6) -> 1.56 | D6: =MAX(0,D5+I6) -> 9171.1538 | E6: 8 | F6: =IF(D6=0,"",(参数!$B$5/参数!$B$6*参数!$B$26)/D6) -> 7.2691689 | G6: =IF(E6="",F6,E6) -> 8 | H6: =D6*G6 -> 73369.231 | I6: =H5*(C6-C5)/C6-H5*参数!$B$13-H5*参数!$B$15*参数!$B$16*((C5+C6)/2)/C6 -> 2504.4872 | J6: =D6*C6 -> 14307 | K6: =IF(G6=0,"",C6*(1-1/G6)/(1-参数!$B$11-参数!$B$12)) -> 1.3760081 | L6: =IF(K6="","",1-K6/C6) -> 0.11794355 | M6: =参数!$B$21 -> 2.8153153 | N6: =IF(G6>M6,"超过安全杠杆",IF(L6<参数!$B$17,"插针风险","OK")) -> 超过安全杠杆
A7: 2 | B7: 0.05 | C7: =C6*(1+B7) -> 1.638 | D7: =MAX(0,D6+I7) -> 12599.418 | E7: 6 | F7: =IF(D7=0,"",(参数!$B$5/参数!$B$6*参数!$B$26)/D7) -> 5.2912495 | G7: =IF(E7="",F7,E7) -> 6 | H7: =D7*G7 -> 75596.511 | I7: =H6*(C7-C6)/C7-H6*参数!$B$13-H6*参数!$B$15*参数!$B$16*((C6+C7)/2)/C7 -> 3428.2647 | J7: =D7*C7 -> 20637.848 | K7: =IF(G7=0,"",C7*(1-1/G7)/(1-参数!$B$11-参数!$B$12)) -> 1.3760081 | L7: =IF(K7="","",1-K7/C7) -> 0.15994624 | M7: =参数!$B$21 -> 2.8153153 | N7: =IF(G7>M7,"超过安全杠杆",IF(L7<参数!$B$17,"插针风险","OK")) -> 超过安全杠杆
A8: 3 | B8: 0.05 | C8: =C7*(1+B8) -> 1.7199 | D8: =MAX(0,D7+I8) -> 16131.755 | E8: 5 | F8: =IF(D8=0,"",(参数!$B$5/参数!$B$6*参数!$B$26)/D8) -> 4.1326356 | G8: =IF(E8="",F8,E8) -> 5 | H8: =D8*G8 -> 80658.777 | I8: =H7*(C8-C7)/C8-H7*参数!$B$13-H7*参数!$B$15*参数!$B$16*((C7+C8)/2)/C8 -> 3532.337 | J8: =D8*C8 -> 27745.006 | K8: =IF(G8=0,"",C8*(1-1/G8)/(1-参数!$B$11-参数!$B$12)) -> 1.3870161 | L8: =IF(K8="","",1-K8/C8) -> 0.19354839 | M8: =参数!$B$21 -> 2.8153153 | N8: =IF(G8>M8,"超过安全杠杆",IF(L8<参数!$B$17,"插针风险","OK")) -> 超过安全杠杆
A9: 4 | B9: 0.07 | C9: =C8*(1+B9) -> 1.840293 | D9: =MAX(0,D8+I9) -> 21336.697 | E9: 4 | F9: =IF(D9=0,"",(参数!$B$5/参数!$B$6*参数!$B$26)/D9) -> 3.1245074 | G9: =IF(E9="",F9,E9) -> 4 | H9: =D9*G9 -> 85346.786 | I9: =H8*(C9-C8)/C9-H8*参数!$B$13-H8*参数!$B$15*参数!$B$16*((C8+C9)/2)/C9 -> 5204.9411 | J9: =D9*C9 -> 39265.773 | K9: =IF(G9=0,"",C9*(1-1/G9)/(1-参数!$B$11-参数!$B$12)) -> 1.3913506 | L9: =IF(K9="","",1-K9/C9) -> 0.24395161 | M9: =参数!$B$21 -> 2.8153153 | N9: =IF(G9>M9,"超过安全杠杆",IF(L9<参数!$B$17,"插针风险","OK")) -> 超过安全杠杆
A10: 5 | B10: 0.1 | C10: =C9*(1+B10) -> 2.0243223 | D10: =MAX(0,D9+I10) -> 29019.847 | E10: 3 | F10: =IF(D10=0,"",(参数!$B$5/参数!$B$6*参数!$B$26)/D10) -> 2.2972784 | G10: =IF(E10="",F10,E10) -> 3 | H10: =D10*G10 -> 87059.541 | I10: =H9*(C10-C9)/C10-H9*参数!$B$13-H9*参数!$B$15*参数!$B$16*((C9+C10)/2)/C10 -> 7683.1504 | J10: =D10*C10 -> 58745.523 | K10: =IF(G10=0,"",C10*(1-1/G10)/(1-参数!$B$11-参数!$B$12)) -> 1.3604317 | L10: =IF(K10="","",1-K10/C10) -> 0.32795699 | M10: =参数!$B$21 -> 2.8153153 | N10: =IF(G10>M10,"超过安全杠杆",IF(L10<参数!$B$17,"插针风险","OK")) -> 超过安全杠杆
A11: 6 | B11: 0.2 | C11: =C10*(1+B11) -> 2.4291868 | D11: =MAX(0,D10+I11) -> 43453.593 | E11: 2 | F11: =IF(D11=0,"",(参数!$B$5/参数!$B$6*参数!$B$26)/D11) -> 1.5342038 | G11: =IF(E11="",F11,E11) -> 2 | H11: =D11*G11 -> 86907.187 | I11: =H10*(C11-C10)/C11-H10*参数!$B$13-H10*参数!$B$15*参数!$B$16*((C10+C11)/2)/C11 -> 14433.746 | J11: =D11*C11 -> 105556.89 | K11: =IF(G11=0,"",C11*(1-1/G11)/(1-参数!$B$11-参数!$B$12)) -> 1.2243885 | L11: =IF(K11="","",1-K11/C11) -> 0.49596774 | M11: =参数!$B$21 -> 2.8153153 | N11: =IF(G11>M11,"超过安全杠杆",IF(L11<参数!$B$17,"插针风险","OK")) -> OK
A12: 7 | B12: 0.35 | C12: =C11*(1+B12) -> 3.2794021 | D12: =MAX(0,D11+I12) -> 65910.249 | E12: 1.5 | F12: =IF(D12=0,"",(参数!$B$5/参数!$B$6*参数!$B$26)/D12) -> 1.0114765 | G12: =IF(E12="",F12,E12) -> 1.5 | H12: =D12*G12 -> 98865.374 | I12: =H11*(C12-C11)/C12-H11*参数!$B$13-H11*参数!$B$15*参数!$B$16*((C11+C12)/2)/C12 -> 22456.656 | J12: =D12*C12 -> 216146.21 | K12: =IF(G12=0,"",C12*(1-1/G12)/(1-参数!$B$11-参数!$B$12)) -> 1.1019496 | L12: =IF(K12="","",1-K12/C12) -> 0.66397849 | M12: =参数!$B$21 -> 2.8153153 | N12: =IF(G12>M12,"超过安全杠杆",IF(L12<参数!$B$17,"插针风险","OK")) -> OK
A13: 8 | B13: 0.5 | C13: =C12*(1+B13) -> 4.9191032 | D13: =MAX(0,D12+I13) -> 98781.339 | E13: 1 | F13: =IF(D13=0,"",(参数!$B$5/参数!$B$6*参数!$B$26)/D13) -> 0.67489131 | G13: =IF(E13="",F13,E13) -> 1 | H13: =D13*G13 -> 98781.339 | I13: =H12*(C13-C12)/C13-H12*参数!$B$13-H12*参数!$B$15*参数!$B$16*((C12+C13)/2)/C13 -> 32871.089 | J13: =D13*C13 -> 485915.6 | K13: =IF(G13=0,"",C13*(1-1/G13)/(1-参数!$B$11-参数!$B$12)) -> 0 | L13: =IF(K13="","",1-K13/C13) -> 1 | M13: =参数!$B$21 -> 2.8153153 | N13: =IF(G13>M13,"超过安全杠杆",IF(L13<参数!$B$17,"插针风险","OK")) -> OK
A14: 9 | B14: 1 | C14: =C13*(1+B14) -> 9.8382064 | D14: =MAX(0,D13+I14) -> 148090.51 | E14: 0.5 | F14: =IF(D14=0,"",(参数!$B$5/参数!$B$6*参数!$B$26)/D14) -> 0.45017513 | G14: =IF(E14="",F14,E14) -> 0.5 | H14: =D14*G14 -> 74045.257 | I14: =H13*(C14-C13)/C14-H13*参数!$B$13-H13*参数!$B$15*参数!$B$16*((C13+C14)/2)/C14 -> 49309.175 | J14: =D14*C14 -> 1456945 | K14: =IF(G14=0,"",C14*(1-1/G14)/(1-参数!$B$11-参数!$B$12)) -> -9.9175468 | L14: =IF(K14="","",1-K14/C14) -> 2.0080645 | M14: =参数!$B$21 -> 2.8153153 | N14: =IF(G14>M14,"超过安全杠杆",IF(L14<参数!$B$17,"插针风险","OK")) -> OK
A15: 10 | B15: 2 | C15: =C14*(1+B15) -> 29.514619 | D15: =MAX(0,D14+I15) -> 197394.78 | E15: 0.25 | F15: =IF(D15=0,"",(参数!$B$5/参数!$B$6*参数!$B$26)/D15) -> 0.33773267 | G15: =IF(E15="",F15,E15) -> 0.25 | H15: =D15*G15 -> 49348.695 | I15: =H14*(C15-C14)/C15-H14*参数!$B$13-H14*参数!$B$15*参数!$B$16*((C14+C15)/2)/C15 -> 49304.268 | J15: =D15*C15 -> 5826031.8 | K15: =IF(G15=0,"",C15*(1-1/G15)/(1-参数!$B$11-参数!$B$12)) -> -89.257921 | L15: =IF(K15="","",1-K15/C15) -> 4.0241935 | M15: =参数!$B$21 -> 2.8153153 | N15: =IF(G15>M15,"超过安全杠杆",IF(L15<参数!$B$17,"插针风险","OK")) -> OK
A16: 11 | B16: 5 | C16: =C15*(1+B16) -> 177.08771 | D16: =MAX(0,D15+I16) -> 238480.45 | E16: 0.1 | F16: =IF(D16=0,"",(参数!$B$5/参数!$B$6*参数!$B$26)/D16) -> 0.27954772 | G16: =IF(E16="",F16,E16) -> 0.1 | H16: =D16*G16 -> 23848.045 | I16: =H15*(C16-C15)/C16-H15*参数!$B$13-H15*参数!$B$15*参数!$B$16*((C15+C16)/2)/C16 -> 41085.668 | J16: =D16*C16 -> 42231958 | K16: =IF(G16=0,"",C16*(1-1/G16)/(1-参数!$B$11-参数!$B$12)) -> -1606.6426 | L16: =IF(K16="","",1-K16/C16) -> 10.072581 | M16: =参数!$B$21 -> 2.8153153 | N16: =IF(G16>M16,"超过安全杠杆",IF(L16<参数!$B$17,"插针风险","OK")) -> OK
A19: 使用说明
A20: 黄色列“本段涨幅”和“手动杠杆”可以直接改，模拟截图里那种 4%、5%、7%、10%、20% 上涨后逐步降杠杆的路径。
A21: 币本位本金 = 上一段币本位本金 + 上一段维持仓位带来的币本位收益；费用和资金费会从币本位收益里扣掉。
A22: 自动目标杠杆默认按“初始币本金 * 参数页风险预算单笔杠杆”作为目标币仓；如果你想设固定目标仓位，可以直接改 F 列公式。
A23: 这个模式和固定目标杠杆滚仓的区别是：它越涨越降杠杆，目标是维持大币数仓位并降低后期爆仓风险。

Sheet 敏感性分析
A1: 敏感性分析
A2: 不同滚仓段数和目标杠杆下的最终本金倍数。已纳入手续费、滑点和资金费；强平风险需同时看检查项。
A4: U本位：最终本金倍数 | B4: 1 | C4: 1.5 | D4: 2 | E4: 2.5 | F4: 2.86 | G4: 备注
A5: 1 | B5: =MAX(0,(1+B$4*((参数!$B$7/参数!$B$6)^(1/$A5)*(1-参数!$B$14)/(1+参数!$B$14)-1)-B$4*参数!$B$13-B$4*((参数!$B$7/参数!$B$6)^(1/$A5)*(1-参数!$B$14)/(1+参数!$B$14))*参数!$B$13-B$4*参数!$B$15*参数!$B$16)^$A5) -> 26.596519 | C5: =MAX(0,(1+C$4*((参数!$B$7/参数!$B$6)^(1/$A5)*(1-参数!$B$14)/(1+参数!$B$14)-1)-C$4*参数!$B$13-C$4*((参数!$B$7/参数!$B$6)^(1/$A5)*(1-参数!$B$14)/(1+参数!$B$14))*参数!$B$13-C$4*参数!$B$15*参数!$B$16)^$A5) -> 39.394778 | D5: =MAX(0,(1+D$4*((参数!$B$7/参数!$B$6)^(1/$A5)*(1-参数!$B$14)/(1+参数!$B$14)-1)-D$4*参数!$B$13-D$4*((参数!$B$7/参数!$B$6)^(1/$A5)*(1-参数!$B$14)/(1+参数!$B$14))*参数!$B$13-D$4*参数!$B$15*参数!$B$16)^$A5) -> 52.193037 | E5: =MAX(0,(1+E$4*((参数!$B$7/参数!$B$6)^(1/$A5)*(1-参数!$B$14)/(1+参数!$B$14)-1)-E$4*参数!$B$13-E$4*((参数!$B$7/参数!$B$6)^(1/$A5)*(1-参数!$B$14)/(1+参数!$B$14))*参数!$B$13-E$4*参数!$B$15*参数!$B$16)^$A5) -> 64.991296 | F5: =MAX(0,(1+F$4*((参数!$B$7/参数!$B$6)^(1/$A5)*(1-参数!$B$14)/(1+参数!$B$14)-1)-F$4*参数!$B$13-F$4*((参数!$B$7/参数!$B$6)^(1/$A5)*(1-参数!$B$14)/(1+参数!$B$14))*参数!$B$13-F$4*参数!$B$15*参数!$B$16)^$A5) -> 74.206043 | G5: =IF(F$4>参数!$B$21,"2.86x 可能超过U本位安全杠杆","") -> 2.86x 可能超过U本位安全杠杆
A6: 2 | B6: =MAX(0,(1+B$4*((参数!$B$7/参数!$B$6)^(1/$A6)*(1-参数!$B$14)/(1+参数!$B$14)-1)-B$4*参数!$B$13-B$4*((参数!$B$7/参数!$B$6)^(1/$A6)*(1-参数!$B$14)/(1+参数!$B$14))*参数!$B$13-B$4*参数!$B$15*参数!$B$16)^$A6) -> 26.51908 | C6: =MAX(0,(1+C$4*((参数!$B$7/参数!$B$6)^(1/$A6)*(1-参数!$B$14)/(1+参数!$B$14)-1)-C$4*参数!$B$13-C$4*((参数!$B$7/参数!$B$6)^(1/$A6)*(1-参数!$B$14)/(1+参数!$B$14))*参数!$B$13-C$4*参数!$B$15*参数!$B$16)^$A6) -> 52.193428 | D6: =MAX(0,(1+D$4*((参数!$B$7/参数!$B$6)^(1/$A6)*(1-参数!$B$14)/(1+参数!$B$14)-1)-D$4*参数!$B$13-D$4*((参数!$B$7/参数!$B$6)^(1/$A6)*(1-参数!$B$14)/(1+参数!$B$14))*参数!$B$13-D$4*参数!$B$15*参数!$B$16)^$A6) -> 86.477649 | E6: =MAX(0,(1+E$4*((参数!$B$7/参数!$B$6)^(1/$A6)*(1-参数!$B$14)/(1+参数!$B$14)-1)-E$4*参数!$B$13-E$4*((参数!$B$7/参数!$B$6)^(1/$A6)*(1-参数!$B$14)/(1+参数!$B$14))*参数!$B$13-E$4*参数!$B$15*参数!$B$16)^$A6) -> 129.37174 | F6: =MAX(0,(1+F$4*((参数!$B$7/参数!$B$6)^(1/$A6)*(1-参数!$B$14)/(1+参数!$B$14)-1)-F$4*参数!$B$13-F$4*((参数!$B$7/参数!$B$6)^(1/$A6)*(1-参数!$B$14)/(1+参数!$B$14))*参数!$B$13-F$4*参数!$B$15*参数!$B$16)^$A6) -> 165.58672 | G6: =IF(F$4>参数!$B$21,"2.86x 可能超过U本位安全杠杆","") -> 2.86x 可能超过U本位安全杠杆
A7: 4 | B7: =MAX(0,(1+B$4*((参数!$B$7/参数!$B$6)^(1/$A7)*(1-参数!$B$14)/(1+参数!$B$14)-1)-B$4*参数!$B$13-B$4*((参数!$B$7/参数!$B$6)^(1/$A7)*(1-参数!$B$14)/(1+参数!$B$14))*参数!$B$13-B$4*参数!$B$15*参数!$B$16)^$A7) -> 26.348859 | C7: =MAX(0,(1+C$4*((参数!$B$7/参数!$B$6)^(1/$A7)*(1-参数!$B$14)/(1+参数!$B$14)-1)-C$4*参数!$B$13-C$4*((参数!$B$7/参数!$B$6)^(1/$A7)*(1-参数!$B$14)/(1+参数!$B$14))*参数!$B$13-C$4*参数!$B$15*参数!$B$16)^$A7) -> 70.577641 | D7: =MAX(0,(1+D$4*((参数!$B$7/参数!$B$6)^(1/$A7)*(1-参数!$B$14)/(1+参数!$B$14)-1)-D$4*参数!$B$13-D$4*((参数!$B$7/参数!$B$6)^(1/$A7)*(1-参数!$B$14)/(1+参数!$B$14))*参数!$B$13-D$4*参数!$B$15*参数!$B$16)^$A7) -> 155.49854 | E7: =MAX(0,(1+E$4*((参数!$B$7/参数!$B$6)^(1/$A7)*(1-参数!$B$14)/(1+参数!$B$14)-1)-E$4*参数!$B$13-E$4*((参数!$B$7/参数!$B$6)^(1/$A7)*(1-参数!$B$14)/(1+参数!$B$14))*参数!$B$13-E$4*参数!$B$15*参数!$B$16)^$A7) -> 300.6645 | F7: =MAX(0,(1+F$4*((参数!$B$7/参数!$B$6)^(1/$A7)*(1-参数!$B$14)/(1+参数!$B$14)-1)-F$4*参数!$B$13-F$4*((参数!$B$7/参数!$B$6)^(1/$A7)*(1-参数!$B$14)/(1+参数!$B$14))*参数!$B$13-F$4*参数!$B$15*参数!$B$16)^$A7) -> 455.47444 | G7: =IF(F$4>参数!$B$21,"2.86x 可能超过U本位安全杠杆","") -> 2.86x 可能超过U本位安全杠杆
A8: 8 | B8: =MAX(0,(1+B$4*((参数!$B$7/参数!$B$6)^(1/$A8)*(1-参数!$B$14)/(1+参数!$B$14)-1)-B$4*参数!$B$13-B$4*((参数!$B$7/参数!$B$6)^(1/$A8)*(1-参数!$B$14)/(1+参数!$B$14))*参数!$B$13-B$4*参数!$B$15*参数!$B$16)^$A8) -> 25.992883 | C8: =MAX(0,(1+C$4*((参数!$B$7/参数!$B$6)^(1/$A8)*(1-参数!$B$14)/(1+参数!$B$14)-1)-C$4*参数!$B$13-C$4*((参数!$B$7/参数!$B$6)^(1/$A8)*(1-参数!$B$14)/(1+参数!$B$14))*参数!$B$13-C$4*参数!$B$15*参数!$B$16)^$A8) -> 89.572897 | D8: =MAX(0,(1+D$4*((参数!$B$7/参数!$B$6)^(1/$A8)*(1-参数!$B$14)/(1+参数!$B$14)-1)-D$4*参数!$B$13-D$4*((参数!$B$7/参数!$B$6)^(1/$A8)*(1-参数!$B$14)/(1+参数!$B$14))*参数!$B$13-D$4*参数!$B$15*参数!$B$16)^$A8) -> 261.47038 | E8: =MAX(0,(1+E$4*((参数!$B$7/参数!$B$6)^(1/$A8)*(1-参数!$B$14)/(1+参数!$B$14)-1)-E$4*参数!$B$13-E$4*((参数!$B$7/参数!$B$6)^(1/$A8)*(1-参数!$B$14)/(1+参数!$B$14))*参数!$B$13-E$4*参数!$B$15*参数!$B$16)^$A8) -> 672.45228 | F8: =MAX(0,(1+F$4*((参数!$B$7/参数!$B$6)^(1/$A8)*(1-参数!$B$14)/(1+参数!$B$14)-1)-F$4*参数!$B$13-F$4*((参数!$B$7/参数!$B$6)^(1/$A8)*(1-参数!$B$14)/(1+参数!$B$14))*参数!$B$13-F$4*参数!$B$15*参数!$B$16)^$A8) -> 1246.3933 | G8: =IF(F$4>参数!$B$21,"2.86x 可能超过U本位安全杠杆","") -> 2.86x 可能超过U本位安全杠杆
A9: 12 | B9: =MAX(0,(1+B$4*((参数!$B$7/参数!$B$6)^(1/$A9)*(1-参数!$B$14)/(1+参数!$B$14)-1)-B$4*参数!$B$13-B$4*((参数!$B$7/参数!$B$6)^(1/$A9)*(1-参数!$B$14)/(1+参数!$B$14))*参数!$B$13-B$4*参数!$B$15*参数!$B$16)^$A9) -> 25.635375 | C9: =MAX(0,(1+C$4*((参数!$B$7/参数!$B$6)^(1/$A9)*(1-参数!$B$14)/(1+参数!$B$14)-1)-C$4*参数!$B$13-C$4*((参数!$B$7/参数!$B$6)^(1/$A9)*(1-参数!$B$14)/(1+参数!$B$14))*参数!$B$13-C$4*参数!$B$15*参数!$B$16)^$A9) -> 98.214627 | D9: =MAX(0,(1+D$4*((参数!$B$7/参数!$B$6)^(1/$A9)*(1-参数!$B$14)/(1+参数!$B$14)-1)-D$4*参数!$B$13-D$4*((参数!$B$7/参数!$B$6)^(1/$A9)*(1-参数!$B$14)/(1+参数!$B$14))*参数!$B$13-D$4*参数!$B$15*参数!$B$16)^$A9) -> 328.65627 | E9: =MAX(0,(1+E$4*((参数!$B$7/参数!$B$6)^(1/$A9)*(1-参数!$B$14)/(1+参数!$B$14)-1)-E$4*参数!$B$13-E$4*((参数!$B$7/参数!$B$6)^(1/$A9)*(1-参数!$B$14)/(1+参数!$B$14))*参数!$B$13-E$4*参数!$B$15*参数!$B$16)^$A9) -> 984.69729 | F9: =MAX(0,(1+F$4*((参数!$B$7/参数!$B$6)^(1/$A9)*(1-参数!$B$14)/(1+参数!$B$14)-1)-F$4*参数!$B$13-F$4*((参数!$B$7/参数!$B$6)^(1/$A9)*(1-参数!$B$14)/(1+参数!$B$14))*参数!$B$13-F$4*参数!$B$15*参数!$B$16)^$A9) -> 2047.8748 | G9: =IF(F$4>参数!$B$21,"2.86x 可能超过U本位安全杠杆","") -> 2.86x 可能超过U本位安全杠杆
A10: 18 | B10: =MAX(0,(1+B$4*((参数!$B$7/参数!$B$6)^(1/$A10)*(1-参数!$B$14)/(1+参数!$B$14)-1)-B$4*参数!$B$13-B$4*((参数!$B$7/参数!$B$6)^(1/$A10)*(1-参数!$B$14)/(1+参数!$B$14))*参数!$B$13-B$4*参数!$B$15*参数!$B$16)^$A10) -> 25.105127 | C10: =MAX(0,(1+C$4*((参数!$B$7/参数!$B$6)^(1/$A10)*(1-参数!$B$14)/(1+参数!$B$14)-1)-C$4*参数!$B$13-C$4*((参数!$B$7/参数!$B$6)^(1/$A10)*(1-参数!$B$14)/(1+参数!$B$14))*参数!$B$13-C$4*参数!$B$15*参数!$B$16)^$A10) -> 103.66937 | D10: =MAX(0,(1+D$4*((参数!$B$7/参数!$B$6)^(1/$A10)*(1-参数!$B$14)/(1+参数!$B$14)-1)-D$4*参数!$B$13-D$4*((参数!$B$7/参数!$B$6)^(1/$A10)*(1-参数!$B$14)/(1+参数!$B$14))*参数!$B$13-D$4*参数!$B$15*参数!$B$16)^$A10) -> 385.95731 | E10: =MAX(0,(1+E$4*((参数!$B$7/参数!$B$6)^(1/$A10)*(1-参数!$B$14)/(1+参数!$B$14)-1)-E$4*参数!$B$13-E$4*((参数!$B$7/参数!$B$6)^(1/$A10)*(1-参数!$B$14)/(1+参数!$B$14))*参数!$B$13-E$4*参数!$B$15*参数!$B$16)^$A10) -> 1313.8905 | F10: =MAX(0,(1+F$4*((参数!$B$7/参数!$B$6)^(1/$A10)*(1-参数!$B$14)/(1+参数!$B$14)-1)-F$4*参数!$B$13-F$4*((参数!$B$7/参数!$B$6)^(1/$A10)*(1-参数!$B$14)/(1+参数!$B$14))*参数!$B$13-F$4*参数!$B$15*参数!$B$16)^$A10) -> 3022.4988 | G10: =IF(F$4>参数!$B$21,"2.86x 可能超过U本位安全杠杆","") -> 2.86x 可能超过U本位安全杠杆
A11: 24 | B11: =MAX(0,(1+B$4*((参数!$B$7/参数!$B$6)^(1/$A11)*(1-参数!$B$14)/(1+参数!$B$14)-1)-B$4*参数!$B$13-B$4*((参数!$B$7/参数!$B$6)^(1/$A11)*(1-参数!$B$14)/(1+参数!$B$14))*参数!$B$13-B$4*参数!$B$15*参数!$B$16)^$A11) -> 24.584481 | C11: =MAX(0,(1+C$4*((参数!$B$7/参数!$B$6)^(1/$A11)*(1-参数!$B$14)/(1+参数!$B$14)-1)-C$4*参数!$B$13-C$4*((参数!$B$7/参数!$B$6)^(1/$A11)*(1-参数!$B$14)/(1+参数!$B$14))*参数!$B$13-C$4*参数!$B$15*参数!$B$16)^$A11) -> 105.21648 | D11: =MAX(0,(1+D$4*((参数!$B$7/参数!$B$6)^(1/$A11)*(1-参数!$B$14)/(1+参数!$B$14)-1)-D$4*参数!$B$13-D$4*((参数!$B$7/参数!$B$6)^(1/$A11)*(1-参数!$B$14)/(1+参数!$B$14))*参数!$B$13-D$4*参数!$B$15*参数!$B$16)^$A11) -> 414.41016 | E11: =MAX(0,(1+E$4*((参数!$B$7/参数!$B$6)^(1/$A11)*(1-参数!$B$14)/(1+参数!$B$14)-1)-E$4*参数!$B$13-E$4*((参数!$B$7/参数!$B$6)^(1/$A11)*(1-参数!$B$14)/(1+参数!$B$14))*参数!$B$13-E$4*参数!$B$15*参数!$B$16)^$A11) -> 1515.6588 | F11: =MAX(0,(1+F$4*((参数!$B$7/参数!$B$6)^(1/$A11)*(1-参数!$B$14)/(1+参数!$B$14)-1)-F$4*参数!$B$13-F$4*((参数!$B$7/参数!$B$6)^(1/$A11)*(1-参数!$B$14)/(1+参数!$B$14))*参数!$B$13-F$4*参数!$B$15*参数!$B$16)^$A11) -> 3698.5734 | G11: =IF(F$4>参数!$B$21,"2.86x 可能超过U本位安全杠杆","") -> 2.86x 可能超过U本位安全杠杆
A13: 币本位：最终本金倍数 | B13: 1 | C13: 1.5 | D13: 2 | E13: 2.5 | F13: 2.86 | G13: 备注 | H13: 每段价格倍数
A14: 1 | B14: =MAX(0,((1+B$13*(1/(1+参数!$B$14)-1/($H14*(1-参数!$B$14)))-B$13*参数!$B$13/(1+参数!$B$14)-B$13*参数!$B$13/($H14*(1-参数!$B$14))-B$13*参数!$B$15*参数!$B$16*2/(1+$H14))*$H14)^$A14) -> 52.288529 | C14: =MAX(0,((1+C$13*(1/(1+参数!$B$14)-1/($H14*(1-参数!$B$14)))-C$13*参数!$B$13/(1+参数!$B$14)-C$13*参数!$B$13/($H14*(1-参数!$B$14))-C$13*参数!$B$15*参数!$B$16*2/(1+$H14))*$H14)^$A14) -> 65.099461 | D14: =MAX(0,((1+D$13*(1/(1+参数!$B$14)-1/($H14*(1-参数!$B$14)))-D$13*参数!$B$13/(1+参数!$B$14)-D$13*参数!$B$13/($H14*(1-参数!$B$14))-D$13*参数!$B$15*参数!$B$16*2/(1+$H14))*$H14)^$A14) -> 77.910392 | E14: =MAX(0,((1+E$13*(1/(1+参数!$B$14)-1/($H14*(1-参数!$B$14)))-E$13*参数!$B$13/(1+参数!$B$14)-E$13*参数!$B$13/($H14*(1-参数!$B$14))-E$13*参数!$B$15*参数!$B$16*2/(1+$H14))*$H14)^$A14) -> 90.721323 | F14: =MAX(0,((1+F$13*(1/(1+参数!$B$14)-1/($H14*(1-参数!$B$14)))-F$13*参数!$B$13/(1+参数!$B$14)-F$13*参数!$B$13/($H14*(1-参数!$B$14))-F$13*参数!$B$15*参数!$B$16*2/(1+$H14))*$H14)^$A14) -> 99.945194 | G14: =IF(F$13>参数!$B$22,"2.86x 通常超过币本位安全杠杆","") -> 2.86x 通常超过币本位安全杠杆 | H14: =(参数!$B$7/参数!$B$6)^(1/$A14) -> 26.666667
